Workbook

Sheet KamstrupData
B1: Active from date | C1: End date | D1: Chose the capability | E1: Auto fill Level 1 | F1: Auto fill Level 2 | G1: Auto fill Level 3 | H1: Not used | I1: Country code | J1: Business Area using/doing the capability | K1: Department or Team using/doing the capability | L1: Chose the application | M1: Auto fill application | N1: Evaluation of Gartner TIME for the application only in relation to this Capability | O1: Classifications for Business Criticality: Administrative Service Business Operational Business Critical Mission Critical. | P1: Business process applying to the capability | Q1: Value Stream applying to the process and application | R1: Value Stream order | S1: Projects involving the current Capability, Process and Application | T1: Comment reletad to the current row
B2: Dates | D2: B-Business Capability | I2: O-Organization | L2: A-Applications | P2: C-Business Context | S2: I-Initiative | T2: Comment
B4: FromDate | C4: EndDate | D4: IdLevel123 | E4: Capbility level 1 | F4: Capbility level 2 | G4: Capbility level 3 | H4: Capbility level 4 | I4: CountryCode | J4: Business Area | K4: DepartmentTeam | L4: NoApplication | M4: Application | N4: Gartner TIME | O4: Business Criticality | P4: NoProcess | Q4: Value Stream | R4: Value Stream Order | S4: Projects | T4: Comment
D5: 1007-Strategic Management-- | E5: =VLOOKUP(D5,'B-Business Capability'!B:H,5,FALSE) -> Strategic Management | F5: =VLOOKUP(D5,'B-Business Capability'!B:H,6,FALSE) -> 0 | G5: =VLOOKUP(D5,'B-Business Capability'!B:H,7,FALSE) -> 0 | I5: DK10 | J5: DK_Executive Management office_Executive Management office | L5: 1 - IFS ERP | M5: =VLOOKUP(L5,'A-Applications'!B:D,3,FALSE) -> IFS ERP | N5: Tolerate | O5: Business Operational | P5: No-NoProcess-- | Q5: =VLOOKUP(KamstrupData[[#This Row],[IdLevel123]],'B-Business Capability'!B:L,10,FALSE) -> N/A | R5: =VLOOKUP(KamstrupData[[#This Row],[IdLevel123]],'B-Business Capability'!B:L,11,FALSE) -> 0 | T5: MJTA
D6: 1022-Finance-Accounting- | E6: =VLOOKUP(D6,'B-Business Capability'!B:H,5,FALSE) -> Finance | F6: =VLOOKUP(D6,'B-Business Capability'!B:H,6,FALSE) -> Accounting | G6: =VLOOKUP(D6,'B-Business Capability'!B:H,7,FALSE) -> 0 | I6: DK10 | J6: DK_Digitalization_EA, Infrastructure and Platforms | K6: DK_Digitalization_EA, Infrastructure and Platforms_Cloud and Platforms | L6: 1 - IFS ERP | M6: =VLOOKUP(L6,'A-Applications'!B:D,3,FALSE) -> IFS ERP | N6: Invest | O6: Administrative Service | P6: P-Not mapped to process-- | Q6: =VLOOKUP(KamstrupData[[#This Row],[IdLevel123]],'B-Business Capability'!B:L,10,FALSE) -> N/A | R6: =VLOOKUP(KamstrupData[[#This Row],[IdLevel123]],'B-Business Capability'!B:L,11,FALSE) -> 0
D7: 1027-Finance-Tax Management- | E7: =VLOOKUP(D7,'B-Business Capability'!B:H,5,FALSE) -> Finance | F7: =VLOOKUP(D7,'B-Business Capability'!B:H,6,FALSE) -> Tax Management | G7: =VLOOKUP(D7,'B-Business Capability'!B:H,7,FALSE) -> 0 | I7: US10 | J7: US_Finance | L7: 1 - IFS ERP | M7: =VLOOKUP(L7,'A-Applications'!B:D,3,FALSE) -> IFS ERP | N7: Tolerate | O7: Business Operational | P7: No-NoProcess-- | Q7: =VLOOKUP(KamstrupData[[#This Row],[IdLevel123]],'B-Business Capability'!B:L,10,FALSE) -> N/A | R7: =VLOOKUP(KamstrupData[[#This Row],[IdLevel123]],'B-Business Capability'!B:L,11,FALSE) -> 0 | T7: JEBL
D8: 1034-Procurement & Logistics-Purchasing- | E8: =VLOOKUP(D8,'B-Business Capability'!B:H,5,FALSE) -> Procurement & Logistics | F8: =VLOOKUP(D8,'B-Business Capability'!B:H,6,FALSE) -> Purchasing | G8: =VLOOKUP(D8,'B-Business Capability'!B:H,7,FALSE) -> 0 | I8: DK10 | J8: Supply Chain | K8: Sourcing | L8: 1 - IFS ERP | M8: =VLOOKUP(L8,'A-Applications'!B:D,3,FALSE) -> IFS ERP | N8: Tolerate | O8: Business Operational | P8: P10-Sourcing-- | Q8: =VLOOKUP(KamstrupData[[#This Row],[IdLevel123]],'B-Business Capability'!B:L,10,FALSE) -> Procure-to-Pay (P2P) | R8: =VLOOKUP(KamstrupData[[#This Row],[IdLevel123]],'B-Business Capability'!B:L,11,FALSE) -> 300 | T8: JEMA
D9: 1034-Procurement & Logistics-Purchasing- | E9: =VLOOKUP(D9,'B-Business Capability'!B:H,5,FALSE) -> Procurement & Logistics | F9: =VLOOKUP(D9,'B-Business Capability'!B:H,6,FALSE) -> Purchasing | G9: =VLOOKUP(D9,'B-Business Capability'!B:H,7,FALSE) -> 0 | I9: US10 | J9: Supply Chain | K9: Sourcing | L9: 1 - IFS ERP | M9: =VLOOKUP(L9,'A-Applications'!B:D,3,FALSE) -> IFS ERP | N9: Tolerate | O9: Business Operational | P9: P10-Sourcing-- | Q9: =VLOOKUP(KamstrupData[[#This Row],[IdLevel123]],'B-Business Capability'!B:L,10,FALSE) -> Procure-to-Pay (P2P) | R9: =VLOOKUP(KamstrupData[[#This Row],[IdLevel123]],'B-Business Capability'!B:L,11,FALSE) -> 300 | T9: JSY
D10: 1035-Procurement & Logistics-Sourcing- | E10: =VLOOKUP(D10,'B-Business Capability'!B:H,5,FALSE) -> Procurement & Logistics | F10: =VLOOKUP(D10,'B-Business Capability'!B:H,6,FALSE) -> Sourcing | G10: =VLOOKUP(D10,'B-Business Capability'!B:H,7,FALSE) -> 0 | I10: DK10 | J10: Supply Chain | K10: Sourcing | L10: 1 - IFS ERP | M10: =VLOOKUP(L10,'A-Applications'!B:D,3,FALSE) -> IFS ERP | N10: Tolerate | O10: Administrative Service | P10: P10-Sourcing-SP10.9-Supplier Phase-Out | Q10: =VLOOKUP(KamstrupData[[#This Row],[IdLevel123]],'B-Business Capability'!B:L,10,FALSE) -> Procure-to-Pay (P2P) | R10: =VLOOKUP(KamstrupData[[#This Row],[IdLevel123]],'B-Business Capability'!B:L,11,FALSE) -> 100 | T10: JEMA, Det er og ændre det data, hvor vi har registreret noget i vedrørende leverandøren.
D11: 1035-Procurement & Logistics-Sourcing- | E11: =VLOOKUP(D11,'B-Business Capability'!B:H,5,FALSE) -> Procurement & Logistics | F11: =VLOOKUP(D11,'B-Business Capability'!B:H,6,FALSE) -> Sourcing | G11: =VLOOKUP(D11,'B-Business Capability'!B:H,7,FALSE) -> 0 | I11: DK10 | J11: Water - Technology Hardware | K11: Mech | L11: 1 - IFS ERP | M11: =VLOOKUP(L11,'A-Applications'!B:D,3,FALSE) -> IFS ERP | N11: Tolerate | O11: Business Operational | P11: P07-Innovation & Solution Development-- | Q11: =VLOOKUP(KamstrupData[[#This Row],[IdLevel123]],'B-Business Capability'!B:L,10,FALSE) -> Procure-to-Pay (P2P) | R11: =VLOOKUP(KamstrupData[[#This Row],[IdLevel123]],'B-Business Capability'!B:L,11,FALSE) -> 100 | T11: DBR, FRFS find capa, for supply change support
D12: 1046-Manufacturing-Change Management- | E12: =VLOOKUP(D12,'B-Business Capability'!B:H,5,FALSE) -> Manufacturing | F12: =VLOOKUP(D12,'B-Business Capability'!B:H,6,FALSE) -> Change Management | G12: =VLOOKUP(D12,'B-Business Capability'!B:H,7,FALSE) -> 0 | I12: DK10 | J12: Supply Chain | L12: 1 - IFS ERP | M12: =VLOOKUP(L12,'A-Applications'!B:D,3,FALSE) -> IFS ERP | N12: Tolerate | O12: Business Critical | P12: P11-Operations-- | Q12: =VLOOKUP(KamstrupData[[#This Row],[IdLevel123]],'B-Business Capability'!B:L,10,FALSE) -> Idea-to-Release (I2R) | R12: =VLOOKUP(KamstrupData[[#This Row],[IdLevel123]],'B-Business Capability'!B:L,11,FALSE) -> 470
D13: 1051-Manufacturing-Product Design & Planning- | E13: =VLOOKUP(D13,'B-Business Capability'!B:H,5,FALSE) -> Manufacturing | F13: =VLOOKUP(D13,'B-Business Capability'!B:H,6,FALSE) -> Product Design & Planning | G13: =VLOOKUP(D13,'B-Business Capability'!B:H,7,FALSE) -> 0 | I13: DK10 | J13: Supply Chain | L13: 1 - IFS ERP | M13: =VLOOKUP(L13,'A-Applications'!B:D,3,FALSE) -> IFS ERP | N13: Tolerate | O13: Business Operational | P13: P11-Operations-- | Q13: =VLOOKUP(KamstrupData[[#This Row],[IdLevel123]],'B-Business Capability'!B:L,10,FALSE) -> Idea-to-Release (I2R) | R13: =VLOOKUP(KamstrupData[[#This Row],[IdLevel123]],'B-Business Capability'!B:L,11,FALSE) -> 450
D14: 1051-Manufacturing-Product Design & Planning- | E14: =VLOOKUP(D14,'B-Business Capability'!B:H,5,FALSE) -> Manufacturing | F14: =VLOOKUP(D14,'B-Business Capability'!B:H,6,FALSE) -> Product Design & Planning | G14: =VLOOKUP(D14,'B-Business Capability'!B:H,7,FALSE) -> 0 | I14: US10 | J14: Supply Chain | L14: 1 - IFS ERP | M14: =VLOOKUP(L14,'A-Applications'!B:D,3,FALSE) -> IFS ERP | N14: Tolerate | O14: Business Operational | P14: P11-Operations-- | Q14: =VLOOKUP(KamstrupData[[#This Row],[IdLevel123]],'B-Business Capability'!B:L,10,FALSE) -> Idea-to-Release (I2R) | R14: =VLOOKUP(KamstrupData[[#This Row],[IdLevel123]],'B-Business Capability'!B:L,11,FALSE) -> 450 | T14: JSY
D15: 1052-Manufacturing-Manufacturing Order Management- | E15: =VLOOKUP(D15,'B-Business Capability'!B:H,5,FALSE) -> Manufacturing | F15: =VLOOKUP(D15,'B-Business Capability'!B:H,6,FALSE) -> Manufacturing Order Management | G15: =VLOOKUP(D15,'B-Business Capability'!B:H,7,FALSE) -> 0 | I15: DK10 | J15: Supply Chain | L15: 1 - IFS ERP | M15: =VLOOKUP(L15,'A-Applications'!B:D,3,FALSE) -> IFS ERP | N15: Tolerate | O15: Business Critical | P15: P11-Operations-- | Q15: =VLOOKUP(KamstrupData[[#This Row],[IdLevel123]],'B-Business Capability'!B:L,10,FALSE) -> Plan-to-Produce (P2P) | R15: =VLOOKUP(KamstrupData[[#This Row],[IdLevel123]],'B-Business Capability'!B:L,11,FALSE) -> 0
D16: 1052-Manufacturing-Manufacturing Order Management- | E16: =VLOOKUP(D16,'B-Business Capability'!B:H,5,FALSE) -> Manufacturing | F16: =VLOOKUP(D16,'B-Business Capability'!B:H,6,FALSE) -> Manufacturing Order Management | G16: =VLOOKUP(D16,'B-Business Capability'!B:H,7,FALSE) -> 0 | I16: US10 | J16: Supply Chain | L16: 1 - IFS ERP | M16: =VLOOKUP(L16,'A-Applications'!B:D,3,FALSE) -> IFS ERP | N16: Tolerate | O16: Business Critical | P16: P11-Operations-- | Q16: =VLOOKUP(KamstrupData[[#This Row],[IdLevel123]],'B-Business Capability'!B:L,10,FALSE) -> Plan-to-Produce (P2P) | R16: =VLOOKUP(KamstrupData[[#This Row],[IdLevel123]],'B-Business Capability'!B:L,11,FALSE) -> 0 | T16: JSY
B17: 45292 | D17: 1052-Manufacturing-Manufacturing Order Management- | E17: =VLOOKUP(D17,'B-Business Capability'!B:H,5,FALSE) -> Manufacturing | F17: =VLOOKUP(D17,'B-Business Capability'!B:H,6,FALSE) -> Manufacturing Order Management | G17: =VLOOKUP(D17,'B-Business Capability'!B:H,7,FALSE) -> 0 | I17: DK10 | J17: DK_Digitalization_Kamstrup Solutions | K17: DK_Digitalization_Kamstrup Solutions_Configuration Management | L17: 1 - IFS ERP | M17: =VLOOKUP(L17,'A-Applications'!B:D,3,FALSE) -> IFS ERP | N17: Invest | O17: Mission Critical | P17: P07-Innovation & Solution Development-SP07.2-Solution Development Model | Q17: =VLOOKUP(KamstrupData[[#This Row],[IdLevel123]],'B-Business Capability'!B:L,10,FALSE) -> Plan-to-Produce (P2P) | R17: =VLOOKUP(KamstrupData[[#This Row],[IdLevel123]],'B-Business Capability'!B:L,11,FALSE) -> 0
D18: 1053-Manufacturing-Manufacturing Steering- | E18: =VLOOKUP(D18,'B-Business Capability'!B:H,5,FALSE) -> Manufacturing | F18: =VLOOKUP(D18,'B-Business Capability'!B:H,6,FALSE) -> Manufacturing Steering | G18: =VLOOKUP(D18,'B-Business Capability'!B:H,7,FALSE) -> 0 | I18: DK10 | J18: Supply Chain | L18: 1 - IFS ERP | M18: =VLOOKUP(L18,'A-Applications'!B:D,3,FALSE) -> IFS ERP | N18: Invest | O18: Business Critical | P18: P11-Operations-SP11.36-Manufacturing Execution Printed Circuit Board Assembly (PCBA) DK | Q18: =VLOOKUP(KamstrupData[[#This Row],[IdLevel123]],'B-Business Capability'!B:L,10,FALSE) -> Plan-to-Produce (P2P) | R18: =VLOOKUP(KamstrupData[[#This Row],[IdLevel123]],'B-Business Capability'!B:L,11,FALSE) -> 0 | T18: Jes, JGN
D19: 1053-Manufacturing-Manufacturing Steering- | E19: =VLOOKUP(D19,'B-Business Capability'!B:H,5,FALSE) -> Manufacturing | F19: =VLOOKUP(D19,'B-Business Capability'!B:H,6,FALSE) -> Manufacturing Steering | G19: =VLOOKUP(D19,'B-Business Capability'!B:H,7,FALSE) -> 0 | I19: DK10 | J19: Supply Chain | L19: 1 - IFS ERP | M19: =VLOOKUP(L19,'A-Applications'!B:D,3,FALSE) -> IFS ERP | N19: Invest | O19: Business Critical | P19: P11-Operations-SP11.3-Manufacturing Planning | Q19: =VLOOKUP(KamstrupData[[#This Row],[IdLevel123]],'B-Business Capability'!B:L,10,FALSE) -> Plan-to-Produce (P2P) | R19: =VLOOKUP(KamstrupData[[#This Row],[IdLevel123]],'B-Business Capability'!B:L,11,FALSE) -> 0 | T19: Jes, JGN
D20: 1053-Manufacturing-Manufacturing Steering- | E20: =VLOOKUP(D20,'B-Business Capability'!B:H,5,FALSE) -> Manufacturing | F20: =VLOOKUP(D20,'B-Business Capability'!B:H,6,FALSE) -> Manufacturing Steering | G20: =VLOOKUP(D20,'B-Business Capability'!B:H,7,FALSE) -> 0 | I20: DK10 | J20: Supply Chain | L20: 1 - IFS ERP | M20: =VLOOKUP(L20,'A-Applications'!B:D,3,FALSE) -> IFS ERP | N20: Invest | O20: Business Critical | P20: P11-Operations-SP11.4-Manufacturing execution Heat & Cooling Temperature Sensors DK | Q20: =VLOOKUP(KamstrupData[[#This Row],[IdLevel123]],'B-Business Capability'!B:L,10,FALSE) -> Plan-to-Produce (P2P) | R20: =VLOOKUP(KamstrupData[[#This Row],[IdLevel123]],'B-Business Capability'!B:L,11,FALSE) -> 0 | T20: Jes, JGN
D21: 1053-Manufacturing-Manufacturing Steering- | E21: =VLOOKUP(D21,'B-Business Capability'!B:H,5,FALSE) -> Manufacturing | F21: =VLOOKUP(D21,'B-Business Capability'!B:H,6,FALSE) -> Manufacturing Steering | G21: =VLOOKUP(D21,'B-Business Capability'!B:H,7,FALSE) -> 0 | I21: DK10 | J21: Supply Chain | L21: 1 - IFS ERP | M21: =VLOOKUP(L21,'A-Applications'!B:D,3,FALSE) -> IFS ERP | N21: Invest | O21: Business Critical | P21: P11-Operations-SP11.5-Manufacturing execution Heat & Cooling DK | Q21: =VLOOKUP(KamstrupData[[#This Row],[IdLevel123]],'B-Business Capability'!B:L,10,FALSE) -> Plan-to-Produce (P2P) | R21: =VLOOKUP(KamstrupData[[#This Row],[IdLevel123]],'B-Business Capability'!B:L,11,FALSE) -> 0 | T21: Jes, JGN
D22: 1053-Manufacturing-Manufacturing Steering- | E22: =VLOOKUP(D22,'B-Business Capability'!B:H,5,FALSE) -> Manufacturing | F22: =VLOOKUP(D22,'B-Business Capability'!B:H,6,FALSE) -> Manufacturing Steering | G22: =VLOOKUP(D22,'B-Business Capability'!B:H,7,FALSE) -> 0 | I22: DK10 | J22: Supply Chain | L22: 1 - IFS ERP | M22: =VLOOKUP(L22,'A-Applications'!B:D,3,FALSE) -> IFS ERP | N22: Invest | O22: Business Critical | P22: P11-Operations-SP11.6-Manufacturing execution Electricity DK | Q22: =VLOOKUP(KamstrupData[[#This Row],[IdLevel123]],'B-Business Capability'!B:L,10,FALSE) -> Plan-to-Produce (P2P) | R22: =VLOOKUP(KamstrupData[[#This Row],[IdLevel123]],'B-Business Capability'!B:L,11,FALSE) -> 0 | T22: Jes, JGN
D23: 1053-Manufacturing-Manufacturing Steering- | E23: =VLOOKUP(D23,'B-Business Capability'!B:H,5,FALSE) -> Manufacturing | F23: =VLOOKUP(D23,'B-Business Capability'!B:H,6,FALSE) -> Manufacturing Steering | G23: =VLOOKUP(D23,'B-Business Capability'!B:H,7,FALSE) -> 0 | I23: DK10 | J23: Supply Chain | L23: 1 - IFS ERP | M23: =VLOOKUP(L23,'A-Applications'!B:D,3,FALSE) -> IFS ERP | N23: Invest | O23: Business Critical | P23: P11-Operations-SP11.7-Manufacturing execution Water DK | Q23: =VLOOKUP(KamstrupData[[#This Row],[IdLevel123]],'B-Business Capability'!B:L,10,FALSE) -> Plan-to-Produce (P2P) | R23: =VLOOKUP(KamstrupData[[#This Row],[IdLevel123]],'B-Business Capability'!B:L,11,FALSE) -> 0 | T23: Jes, JGN
D24: 1053-Manufacturing-Manufacturing Steering- | E24: =VLOOKUP(D24,'B-Business Capability'!B:H,5,FALSE) -> Manufacturing | F24: =VLOOKUP(D24,'B-Business Capability'!B:H,6,FALSE) -> Manufacturing Steering | G24: =VLOOKUP(D24,'B-Business Capability'!B:H,7,FALSE) -> 0 | I24: DK10 | J24: Supply Chain | L24: 1 - IFS ERP | M24: =VLOOKUP(L24,'A-Applications'!B:D,3,FALSE) -> IFS ERP | N24: Invest | O24: Business Critical | P24: P11-Operations-SP11.8-Manufacturing execution Water US | Q24: =VLOOKUP(KamstrupData[[#This Row],[IdLevel123]],'B-Business Capability'!B:L,10,FALSE) -> Plan-to-Produce (P2P) | R24: =VLOOKUP(KamstrupData[[#This Row],[IdLevel123]],'B-Business Capability'!B:L,11,FALSE) -> 0 | T24: Jes, JGN
D25: 1053-Manufacturing-Manufacturing Steering- | E25: =VLOOKUP(D25,'B-Business Capability'!B:H,5,FALSE) -> Manufacturing | F25: =VLOOKUP(D25,'B-Business Capability'!B:H,6,FALSE) -> Manufacturing Steering | G25: =VLOOKUP(D25,'B-Business Capability'!B:H,7,FALSE) -> 0 | I25: DK10 | J25: Supply Chain | L25: 1 - IFS ERP | M25: =VLOOKUP(L25,'A-Applications'!B:D,3,FALSE) -> IFS ERP | N25: Tolerate | O25: Business Critical | P25: P11-Operations-- | Q25: =VLOOKUP(KamstrupData[[#This Row],[IdLevel123]],'B-Business Capability'!B:L,10,FALSE) -> Plan-to-Produce (P2P) | R25: =VLOOKUP(KamstrupData[[#This Row],[IdLevel123]],'B-Business Capability'!B:L,11,FALSE) -> 0
D26: 1053-Manufacturing-Manufacturing Steering- | E26: =VLOOKUP(D26,'B-Business Capability'!B:H,5,FALSE) -> Manufacturing | F26: =VLOOKUP(D26,'B-Business Capability'!B:H,6,FALSE) -> Manufacturing Steering | G26: =VLOOKUP(D26,'B-Business Capability'!B:H,7,FALSE) -> 0 | I26: US10 | J26: Supply Chain | L26: 1 - IFS ERP | M26: =VLOOKUP(L26,'A-Applications'!B:D,3,FALSE) -> IFS ERP | N26: Tolerate | O26: Business Critical | P26: P11-Operations-- | Q26: =VLOOKUP(KamstrupData[[#This Row],[IdLevel123]],'B-Business Capability'!B:L,10,FALSE) -> Plan-to-Produce (P2P) | R26: =VLOOKUP(KamstrupData[[#This Row],[IdLevel123]],'B-Business Capability'!B:L,11,FALSE) -> 0 | T26: JSY
D27: 1087-Strategic Management-Enterprise Effectiveness & Project Management-Develop Projects | E27: =VLOOKUP(D27,'B-Business Capability'!B:H,5,FALSE) -> Strategic Management | F27: =VLOOKUP(D27,'B-Business Capability'!B:H,6,FALSE) -> Enterprise Effectiveness & Project Management | G27: =VLOOKUP(D27,'B-Business Capability'!B:H,7,FALSE) -> Develop Projects | I27: DK10 | J27: Electricity - Product Management | L27: 1 - IFS ERP | M27: =VLOOKUP(L27,'A-Applications'!B:D,3,FALSE) -> IFS ERP | N27: Tolerate | O27: Business Operational | P27: P07-Innovation & Solution Development-SP07.54-Product Management | Q27: =VLOOKUP(KamstrupData[[#This Row],[IdLevel123]],'B-Business Capability'!B:L,10,FALSE) -> N/A | R27: =VLOOKUP(KamstrupData[[#This Row],[IdLevel123]],'B-Business Capability'!B:L,11,FALSE) -> 0 | T27: HTA
B28: 45292 | D28: 1097-People and Culture-Compensation & Benefits- | E28: =VLOOKUP(D28,'B-Business Capability'!B:H,5,FALSE) -> People and Culture | F28: =VLOOKUP(D28,'B-Business Capability'!B:H,6,FALSE) -> Compensation & Benefits | G28: =VLOOKUP(D28,'B-Business Capability'!B:H,7,FALSE) -> 0 | I28: DK10 | J28: Electricity - Technology Hardware | L28: 1 - IFS ERP | M28: =VLOOKUP(L28,'A-Applications'!B:D,3,FALSE) -> IFS ERP | N28: Tolerate | O28: Business Operational | P28: P07-Innovation & Solution Development-- | Q28: =VLOOKUP(KamstrupData[[#This Row],[IdLevel123]],'B-Business Capability'!B:L,10,FALSE) -> Hire-to-Retire (H2R) | R28: =VLOOKUP(KamstrupData[[#This Row],[IdLevel123]],'B-Business Capability'!B:L,11,FALSE) -> 700 | S28: P&C-ASIS | T28: JKI
B29: 45292 | D29: 1097-People and Culture-Compensation & Benefits- | E29: =VLOOKUP(D29,'B-Business Capability'!B:H,5,FALSE) -> People and Culture | F29: =VLOOKUP(D29,'B-Business Capability'!B:H,6,FALSE) -> Compensation & Benefits | G29: =VLOOKUP(D29,'B-Business Capability'!B:H,7,FALSE) -> 0 | I29: DK10 | J29: Heat/Cooling - Technology Hardware | K29: Concentrators | L29: 1 - IFS ERP | M29: =VLOOKUP(L29,'A-Applications'!B:D,3,FALSE) -> IFS ERP | N29: Tolerate | O29: Administrative Service | P29: P34-Salary & Incentives-SP34.7-Registration of working hours | Q29: =VLOOKUP(KamstrupData[[#This Row],[IdLevel123]],'B-Business Capability'!B:L,10,FALSE) -> Hire-to-Retire (H2R) | R29: =VLOOKUP(KamstrupData[[#This Row],[IdLevel123]],'B-Business Capability'!B:L,11,FALSE) -> 700 | S29: P&C-ASIS | T29: JESP, RKL
B30: 45292 | D30: 1097-People and Culture-Compensation & Benefits- | E30: =VLOOKUP(D30,'B-Business Capability'!B:H,5,FALSE) -> People and Culture | F30: =VLOOKUP(D30,'B-Business Capability'!B:H,6,FALSE) -> Compensation & Benefits | G30: =VLOOKUP(D30,'B-Business Capability'!B:H,7,FALSE) -> 0 | I30: DK10 | J30: Heat/Cooling - Technology Hardware | K30: Embeded Software | L30: 1 - IFS ERP | M30: =VLOOKUP(L30,'A-Applications'!B:D,3,FALSE) -> IFS ERP | N30: Tolerate | O30: Administrative Service | P30: P34-Salary & Incentives-SP34.7-Registration of working hours | Q30: =VLOOKUP(KamstrupData[[#This Row],[IdLevel123]],'B-Business Capability'!B:L,10,FALSE) -> Hire-to-Retire (H2R) | R30: =VLOOKUP(KamstrupData[[#This Row],[IdLevel123]],'B-Business Capability'!B:L,11,FALSE) -> 700 | S30: P&C-ASIS | T30: BRR
B31: 45292 | D31: 1097-People and Culture-Compensation & Benefits- | E31: =VLOOKUP(D31,'B-Business Capability'!B:H,5,FALSE) -> People and Culture | F31: =VLOOKUP(D31,'B-Business Capability'!B:H,6,FALSE) -> Compensation & Benefits | G31: =VLOOKUP(D31,'B-Business Capability'!B:H,7,FALSE) -> 0 | I31: DK10 | J31: Heat/Cooling - Technology Hardware | K31: H/C Meters | L31: 1 - IFS ERP | M31: =VLOOKUP(L31,'A-Applications'!B:D,3,FALSE) -> IFS ERP | N31: Tolerate | O31: Administrative Service | P31: P34-Salary & Incentives-SP34.7-Registration of working hours | Q31: =VLOOKUP(KamstrupData[[#This Row],[IdLevel123]],'B-Business Capability'!B:L,10,FALSE) -> Hire-to-Retire (H2R) | R31: =VLOOKUP(KamstrupData[[#This Row],[IdLevel123]],'B-Business Capability'!B:L,11,FALSE) -> 700 | S31: P&C-ASIS | T31: JESP
B32: 45292 | D32: 1097-People and Culture-Compensation & Benefits- | E32: =VLOOKUP(D32,'B-Business Capability'!B:H,5,FALSE) -> People and Culture | F32: =VLOOKUP(D32,'B-Business Capability'!B:H,6,FALSE) -> Compensation & Benefits | G32: =VLOOKUP(D32,'B-Business Capability'!B:H,7,FALSE) -> 0 | I32: DK10 | J32: Heat/Cooling - Technology Hardware | K32: Hardware | L32: 1 - IFS ERP | M32: =VLOOKUP(L32,'A-Applications'!B:D,3,FALSE) -> IFS ERP | N32: Tolerate | O32: Administrative Service | P32: P34-Salary & Incentives-SP34.7-Registration of working hours | Q32: =VLOOKUP(KamstrupData[[#This Row],[IdLevel123]],'B-Business Capability'!B:L,10,FALSE) -> Hire-to-Retire (H2R) | R32: =VLOOKUP(KamstrupData[[#This Row],[IdLevel123]],'B-Business Capability'!B:L,11,FALSE) -> 700 | S32: P&C-ASIS | T32: BOR
B33: 45292 | D33: 1097-People and Culture-Compensation & Benefits- | E33: =VLOOKUP(D33,'B-Business Capability'!B:H,5,FALSE) -> People and Culture | F33: =VLOOKUP(D33,'B-Business Capability'!B:H,6,FALSE) -> Compensation & Benefits | G33: =VLOOKUP(D33,'B-Business Capability'!B:H,7,FALSE) -> 0 | I33: DK10 | J33: Heat/Cooling - Technology Hardware | K33: Tech. Lead | L33: 1 - IFS ERP | M33: =VLOOKUP(L33,'A-Applications'!B:D,3,FALSE) -> IFS ERP | N33: Tolerate | O33: Administrative Service | P33: P34-Salary & Incentives-SP34.7-Registration of working hours | Q33: =VLOOKUP(KamstrupData[[#This Row],[IdLevel123]],'B-Business Capability'!B:L,10,FALSE) -> Hire-to-Retire (H2R) | R33: =VLOOKUP(KamstrupData[[#This Row],[IdLevel123]],'B-Business Capability'!B:L,11,FALSE) -> 700 | S33: P&C-ASIS | T33: JESP, FHA
B34: 45292 | D34: 1097-People and Culture-Compensation & Benefits- | E34: =VLOOKUP(D34,'B-Business Capability'!B:H,5,FALSE) -> People and Culture | F34: =VLOOKUP(D34,'B-Business Capability'!B:H,6,FALSE) -> Compensation & Benefits | G34: =VLOOKUP(D34,'B-Business Capability'!B:H,7,FALSE) -> 0 | I34: DK10 | J34: Water - Technology Hardware | K34: Hardware | L34: 1 - IFS ERP | M34: =VLOOKUP(L34,'A-Applications'!B:D,3,FALSE) -> IFS ERP | N34: Tolerate | O34: Administrative Service | P34: P34-Salary & Incentives-SP34.7-Registration of working hours | Q34: =VLOOKUP(KamstrupData[[#This Row],[IdLevel123]],'B-Business Capability'!B:L,10,FALSE) -> Hire-to-Retire (H2R) | R34: =VLOOKUP(KamstrupData[[#This Row],[IdLevel123]],'B-Business Capability'!B:L,11,FALSE) -> 700 | S34: P&C-ASIS | T34: KEA
B35: 45292 | D35: 1097-People and Culture-Compensation & Benefits- | E35: =VLOOKUP(D35,'B-Business Capability'!B:H,5,FALSE) -> People and Culture | F35: =VLOOKUP(D35,'B-Business Capability'!B:H,6,FALSE) -> Compensation & Benefits | G35: =VLOOKUP(D35,'B-Business Capability'!B:H,7,FALSE) -> 0 | I35: DK10 | J35: Water - Technology Hardware | K35: Tech | L35: 1 - IFS ERP | M35: =VLOOKUP(L35,'A-Applications'!B:D,3,FALSE) -> IFS ERP | N35: Tolerate | O35: Business Operational | P35: P07-Innovation & Solution Development-- | Q35: =VLOOKUP(KamstrupData[[#This Row],[IdLevel123]],'B-Business Capability'!B:L,10,FALSE) -> Hire-to-Retire (H2R) | R35: =VLOOKUP(KamstrupData[[#This Row],[IdLevel123]],'B-Business Capability'!B:L,11,FALSE) -> 700 | S35: P&C-ASIS | T35: JDP
D36: 1101-Digital Platform and Operations-AI, Data & Analytics-Gather Data | E36: =VLOOKUP(D36,'B-Business Capability'!B:H,5,FALSE) -> Digital Platform and Operations | F36: =VLOOKUP(D36,'B-Business Capability'!B:H,6,FALSE) -> AI, Data & Analytics | G36: =VLOOKUP(D36,'B-Business Capability'!B:H,7,FALSE) -> Gather Data | I36: US10 | J36: US_Digitalization | L36: 1 - IFS ERP | M36: =VLOOKUP(L36,'A-Applications'!B:D,3,FALSE) -> IFS ERP | N36: Tolerate | O36: Business Critical | P36: No-NoProcess-- | Q36: =VLOOKUP(KamstrupData[[#This Row],[IdLevel123]],'B-Business Capability'!B:L,10,FALSE) -> N/A | R36: =VLOOKUP(KamstrupData[[#This Row],[IdLevel123]],'B-Business Capability'!B:L,11,FALSE) -> 0 | T36: WAPT
D37: 1107-Digital Management-IT Strategy & Transformation-IT Project Management | E37: =VLOOKUP(D37,'B-Business Capability'!B:H,5,FALSE) -> Digital Management | F37: =VLOOKUP(D37,'B-Business Capability'!B:H,6,FALSE) -> IT Strategy & Transformation | G37: =VLOOKUP(D37,'B-Business Capability'!B:H,7,FALSE) -> IT Project Management | I37: DK10 | J37: DK_Digitalization_Kamstrup Solutions | K37: DK_Digitalization_Kamstrup Solutions_Corporate Solutions | L37: 1 - IFS ERP | M37: =VLOOKUP(L37,'A-Applications'!B:D,3,FALSE) -> IFS ERP | N37: Tolerate | O37: Administrative Service | P37: P33-Project Management-SP33.4-IT Projects | Q37: =VLOOKUP(KamstrupData[[#This Row],[IdLevel123]],'B-Business Capability'!B:L,10,FALSE) -> N/A | R37: =VLOOKUP(KamstrupData[[#This Row],[IdLevel123]],'B-Business Capability'!B:L,11,FALSE) -> 0 | T37: KRTI
D38: 1123-Finance-Accounting-Inventory Valuation | E38: =VLOOKUP(D38,'B-Business Capability'!B:H,5,FALSE) -> Finance | F38: =VLOOKUP(D38,'B-Business Capability'!B:H,6,FALSE) -> Accounting | G38: =VLOOKUP(D38,'B-Business Capability'!B:H,7,FALSE) -> Inventory Valuation | I38: DK10 | J38: DK_Finance | L38: 1 - IFS ERP | M38: =VLOOKUP(L38,'A-Applications'!B:D,3,FALSE) -> IFS ERP | N38: Tolerate | O38: Administrative Service | P38: P-Not mapped to process-- | Q38: =VLOOKUP(KamstrupData[[#This Row],[IdLevel123]],'B-Business Capability'!B:L,10,FALSE) -> N/A | R38: =VLOOKUP(KamstrupData[[#This Row],[IdLevel123]],'B-Business Capability'!B:L,11,FALSE) -> 0
D39: 1123-Finance-Accounting-Inventory Valuation | E39: =VLOOKUP(D39,'B-Business Capability'!B:H,5,FALSE) -> Finance | F39: =VLOOKUP(D39,'B-Business Capability'!B:H,6,FALSE) -> Accounting | G39: =VLOOKUP(D39,'B-Business Capability'!B:H,7,FALSE) -> Inventory Valuation | I39: US10 | J39: US_Finance | L39: 1 - IFS ERP | M39: =VLOOKUP(L39,'A-Applications'!B:D,3,FALSE) -> IFS ERP | N39: Tolerate | O39: Business Operational | P39: No-NoProcess-- | Q39: =VLOOKUP(KamstrupData[[#This Row],[IdLevel123]],'B-Business Capability'!B:L,10,FALSE) -> N/A | R39: =VLOOKUP(KamstrupData[[#This Row],[IdLevel123]],'B-Business Capability'!B:L,11,FALSE) -> 0 | T39: JEBL
D40: 1123-Finance-Accounting-Inventory Valuation | E40: =VLOOKUP(D40,'B-Business Capability'!B:H,5,FALSE) -> Finance | F40: =VLOOKUP(D40,'B-Business Capability'!B:H,6,FALSE) -> Accounting | G40: =VLOOKUP(D40,'B-Business Capability'!B:H,7,FALSE) -> Inventory Valuation | I40: NL10 | J40: NL_Finance | L40: 1 - IFS ERP | M40: =VLOOKUP(L40,'A-Applications'!B:D,3,FALSE) -> IFS ERP | N40: Tolerate | O40: Administrative Service | P40: P-Not mapped to process-- | Q40: =VLOOKUP(KamstrupData[[#This Row],[IdLevel123]],'B-Business Capability'!B:L,10,FALSE) -> N/A | R40: =VLOOKUP(KamstrupData[[#This Row],[IdLevel123]],'B-Business Capability'!B:L,11,FALSE) -> 0
D41: 1123-Finance-Accounting-Inventory Valuation | E41: =VLOOKUP(D41,'B-Business Capability'!B:H,5,FALSE) -> Finance | F41: =VLOOKUP(D41,'B-Business Capability'!B:H,6,FALSE) -> Accounting | G41: =VLOOKUP(D41,'B-Business Capability'!B:H,7,FALSE) -> Inventory Valuation | I41: FR10 | J41: FR_Finance | L41: 1 - IFS ERP | M41: =VLOOKUP(L41,'A-Applications'!B:D,3,FALSE) -> IFS ERP | N41: Tolerate | O41: Business Critical | P41: P-Not mapped to process-- | Q41: =VLOOKUP(KamstrupData[[#This Row],[IdLevel123]],'B-Business Capability'!B:L,10,FALSE) -> N/A | R41: =VLOOKUP(KamstrupData[[#This Row],[IdLevel123]],'B-Business Capability'!B:L,11,FALSE) -> 0
...

Sheet A-Applications
D1: Name of the application | E1: Application group | F1: Introduction date of application. (Before 1/8-2025 all applications are set to 01-01-2025) | G1: Install Type - On Prem - Cloud - 3 party hosted - Edge Computing - Distributed Applications | H1: The Gartner TIME (Tolerate, Invest, Migrate, Eliminate) framework is the industry standard for planning and executing an application rationalization. It is a proven methodology for maximizing the business value of your application portfolio. | J1: Vendor Kamstrup purchace the application from | L1: Consultancy for the application | M1: The number of users for the application | N1: The current stage of the application | O1: End of life or Phase out date for the application (Format 31-06-2026) | R1: The URL of the application | S1: Business Owner of the application. Used for applications with no cost if handled in business | V1: Owner of the application. From cost sheet or if empty from Business owner | W1: Delete,Superusers of the application | Y1: Delete | Z1: EA Information related to closure of the application | AA1: Not relevant, SLA for the application | AB1: Not relevant, License responsible of the application | AC1: Sub component to applicatoin | AD1: Which applications are supported by the application. Eg. READy, OMNIA, etc | AE1: Primary in relation to cleanup track | AF1: The application contain AI features. If Yes the risk should be evaluated. | AG1: Set to "No" if the application are not used in capability mapping. Used for server licenses and so. | AH1: If the application are part of a Platform chose the platform. | AI1: Note on the application | AJ1: The recomendation for clean up | AK1: Reason for the recommendation | AL1: Workpackage size of the clousure (S, M, Project) | AM1: Security approved application | AN1: Security approved date | AO1: Security debt. Low Medium High (Inveigate are beeing security investigated) | AP1: Is this application seen as a crown jewel
H2: https://www.leanix.net/en/download/applying-the-gartner-time-framework-for-application-rationalization?utm_term=gartner%20time%20model&utm_source=bing&utm_medium=ppc&utm_campaign=EMEA-NORDIC_Application-Rationalization_AR_Search_ENG_B&hsa_acc=9751618594&hsa_cam=590193139&hsa_grp=1136896741662464&hsa_kw=gartner%20time%20model&hsa_mt=e&hsa_net=bing&hsa_src=o&hsa_tgt=kwd-71056741979861:loc-53&hsa_ad=&hsa_ver=3&msclkid=a7b7b4e697911d431c1dd255b34cacf3&utm_content=NORDIC_gartner-time-framework
B3: NoApplication | C3: No | D3: Application | E3: Application Group | F3: Introduction date | G3: Install type | H3: Gartner TIME | I3: Application Type | J3: Software Vendor | K3: ItemNumber | L3: Consultancy | M3: User base | N3: Lifecycle stage status | O3: Expected End-of-Life Year | P3: Replaced by | Q3: Details | R3: URL | S3: Business Owner | T3: Supported by Group IT | U3: Details2 | V3: Owner | W3: Super User | X3: Named users | Y3: OLD-Data integration | Z3: Temp | AA3: SLA | AB3: Licens responsible | AC3: Sub component to | AD3: Supporting applications | AE3: Org | AF3: AI | AG3: Used in capabilitiy mapping | AH3: Platform | AI3: Clean up: Note | AJ3: Clean up: Recomendation | AK3: Clean up: Reason | AL3: Clean up: WP Size | AM3: Security approved | AN3: Security Approved date | AO3: Security debt | AP3: Crown Jewels
B4: =_xlfn.CONCAT(Applications[[#This Row],[No]]," - ",Applications[[#This Row],[Application]]) -> 1 - IFS ERP | C4: 1 | D4: IFS ERP | E4: Enterprise Platforms | F4: 45658 | G4: On Premise | H4: Invest | I4: Standard solutions | J4: IFS AB | L4: IFS | M4: 1000-> | N4: 1-Strategic | O4: 46813 | Q4: IFS Apps 10 has End of life 1-3-2028. Transsition for new version are projected. | T4: X | U4: Ny licensaftale, generel prisstigning | V4: =_xlfn.XLOOKUP(Applications[[#This Row],[NoApplication]],#REF!,#REF!,Applications[[#This Row],[Business Owner]],0,1) -> #REF! | AB4: KRTI | AE4: Finans, Project | AH4: IFS | AI4: Note for cleanup | AJ4: Keep as strategic | AK4: It is our ERP system | AM4: Yes | AN4: 45658 | AO4: Low | AP4: Crown Jewel_1
B5: =_xlfn.CONCAT(Applications[[#This Row],[No]]," - ",Applications[[#This Row],[Application]]) -> 2 - QAD ERP | C5: 2 | D5: QAD ERP | E5: Business | F5: 45658 | G5: On Premise | H5: Eliminate | I5: Standard solutions | J5: QAD Inc. | L5: Kamstrup | M5: 50-99 | N5: 8-Phase out | O5: 47484 | P5: IFS ERP | Q5: QAD ERP: QAD ERP is a cloud-based enterprise resource planning solution designed specifically for manufacturers. It offers comprehensive solutions for supply chain management, production planning, inventory control, quality management, and regulatory compliance | T5: X | U5: Old ERP system, are only used for viewing of old data. Serial no., Sales invoice, Purchase invoice. Comment 20/11-2024 Ole F har talt lidt med div. I Service vedr. deres aktuelle brug af systemet. Det lyder til (og der kommer en opfølgning på det) at der er brug for meget lidt data. Så jeg vil foreslå at vi laver en analyse / export af disse data til et Excel ark, og derefter officielt lukker systemet 😊 /Ole | V5: =_xlfn.XLOOKUP(Applications[[#This Row],[NoApplication]],#REF!,#REF!,Applications[[#This Row],[Business Owner]],0,1) -> #REF! | AB5: KRTI | AE5: Supply Chain | AH5: QAD | AI5: Jf. bogføringsloven skal noget data gemmes i 5 år (sidste fakturering i 2021). Fra Ole: Jeg tænker det betyder at MFG (som er endnu ældre - data fra 1997 .. 2011) også skal med. Blot til info: - Tænker det er et projekt o Vi skal have information om vores serienumre i mindst 20 år så vidt jeg ved. o Og mere detaljeret i ca 10 år o Begge dele må kunne gemmes i BI på en eller anden måde o Det vil også kræve ændringer i Integration – da de så vil skulle lave serial lookup i BI istedet for i QAD/MFG - En anden udfordring er nok at jeg er den eneste med QAD/MFG viden i Kamstrup. Ole | AL5: M
B6: =_xlfn.CONCAT(Applications[[#This Row],[No]]," - ",Applications[[#This Row],[Application]]) -> 3 - Aras Innovator PLM | C6: 3 | D6: Aras Innovator PLM | E6: Business | F6: 45658 | G6: On Premise | I6: Standard solutions | J6: Aras Corporation | L6: Aras | M6: 100-499 | N6: 1-Strategic | O6: 54788 | Q6: Aras Innovator PLM: Aras Innovator PLM is a flexible, scalable, and upgradeable product lifecycle management software. It supports manufacturers of complex, connected products in digitally transforming their engineering business. It includes features like parts management, change management, document management, and quality management | T6: X | U6: non-standard / potentiale for forbedring | V6: =_xlfn.XLOOKUP(Applications[[#This Row],[NoApplication]],#REF!,#REF!,Applications[[#This Row],[Business Owner]],0,1) -> #REF! | X6: JES, AOE, FHB | AB6: FRFS | AE6: Supply Chain | AH6: Aras Innovator
B7: =_xlfn.CONCAT(Applications[[#This Row],[No]]," - ",Applications[[#This Row],[Application]]) -> 4 - Microsoft Dynamics 365 CE (Sales) | C7: 4 | D7: Microsoft Dynamics 365 CE (Sales) | E7: Enterprise Platforms | F7: 45658 | G7: Cloud | I7: Standard solutions | J7: Microsoft | K7: DGP-00003 | L7: Netcompany | M7: 100-499 | N7: 1-Strategic | O7: 54788 | Q7: Microsoft Dynamics 365 CE (Sales): Microsoft Dynamics 365 Customer Engagement (CE) Sales is a customer relationship management (CRM) solution that helps sales teams build strong relationships with customers, take actions based on insights, and close deals faster. It includes features like account and contact management, lead and opportunity management, and sales forecasting | R7: https://kamstrup.crm4.dynamics.com/ | S7: MIBN | T7: X | V7: =_xlfn.XLOOKUP(Applications[[#This Row],[NoApplication]],#REF!,#REF!,Applications[[#This Row],[Business Owner]],0,1) -> #REF! | AA7: SLA | AB7: Susanne, JTBN | AE7: Sales & Marketing | AF7: Yes | AH7: Dynamics 365
B8: =_xlfn.CONCAT(Applications[[#This Row],[No]]," - ",Applications[[#This Row],[Application]]) -> 5 - Oracle CPQ | C8: 5 | D8: Oracle CPQ | E8: Enterprise Platforms | F8: 45658 | I8: Standard solutions | J8: Oracle Corporation | L8: Solutionspace | N8: 1-Strategic | O8: 54788 | Q8: Oracle CPQ: Oracle Configure, Price, Quote (CPQ) is a cloud-based application that helps sellers configure the right mix of products or services and create accurate, professional quotes to quickly meet their customers’ pricing needs. It streamlines the entire opportunity-to-quote-to-order process | T8: X | U8: General stigning | V8: =_xlfn.XLOOKUP(Applications[[#This Row],[NoApplication]],#REF!,#REF!,Applications[[#This Row],[Business Owner]],0,1) -> #REF! | AB8: JTBN | AE8: Sales & Marketing | AH8: Oracle
B9: =_xlfn.CONCAT(Applications[[#This Row],[No]]," - ",Applications[[#This Row],[Application]]) -> 6 - ServiceNow | C9: 6 | D9: ServiceNow | E9: Business | F9: 45658 | G9: Cloud | H9: Invest | I9: Standard solutions | J9: ServiceNow Inc. | L9: Devoteam | M9: 1000-> | N9: 1-Strategic | O9: 54788 | Q9: ServiceNow: ServiceNow is a cloud-based enterprise workflow automation platform delivered as Software-as-a-Service (SaaS). It automates various business processes, including IT service management, customer service management, and project approvals, on a single, centralized platform | T9: X | U9: ITSM, Web portal | V9: =_xlfn.XLOOKUP(Applications[[#This Row],[NoApplication]],#REF!,#REF!,Applications[[#This Row],[Business Owner]],0,1) -> #REF! | AB9: JEHT | AE9: Supply Chain | AF9: Yes - Minimal Risk | AH9: ServiceNow
B10: =_xlfn.CONCAT(Applications[[#This Row],[No]]," - ",Applications[[#This Row],[Application]]) -> 7 - Reliance | C10: 7 | D10: Reliance | E10: Quality Management System | F10: 45658 | G10: Cloud | I10: Standard solutions | J10: Reliance Industries Limited | L10: ETQ | N10: 8-Phase out | O10: 46477 | Q10: Reliance: Reliance is a governance, risk, and compliance (GRC) software solution that helps organizations streamline their risk management processes, ensure regulatory compliance, and enhance overall operational efficiency | T10: X | U10: QMS - Quality Management System | V10: =_xlfn.XLOOKUP(Applications[[#This Row],[NoApplication]],#REF!,#REF!,Applications[[#This Row],[Business Owner]],0,1) -> #REF! | AE10: Quality | AI10: Phase out and move to IFS, ServiceNow and IPW. Info on phase out from KRNO. | AL10: Project-initiated
B11: =_xlfn.CONCAT(Applications[[#This Row],[No]]," - ",Applications[[#This Row],[Application]]) -> 8 - Neuron | C11: 8 | D11: Neuron | E11: Integration Platforms | F11: 45658 | I11: Standard solutions | J11: Neuron ESB | L11: Integrator | N11: 8-Phase out | O11: 46387 | P11: Azure | Q11: Neuron: Neuron is a simulation environment for modeling individual neurons and networks of neurons. It provides tools for building, managing, and using models in a way that is numerically sound and computationally efficient | T11: Yes | U11: Integration | V11: =_xlfn.XLOOKUP(Applications[[#This Row],[NoApplication]],#REF!,#REF!,Applications[[#This Row],[Business Owner]],0,1) -> #REF! | AB11: FFM | AC11: 8 - Neuron | AE11: Digitalization | AI11: Project of phase out are started with Jeyant in integration team | AL11: Project-initiated
B12: =_xlfn.CONCAT(Applications[[#This Row],[No]]," - ",Applications[[#This Row],[Application]]) -> 9 - Orbit | C12: 9 | D12: Orbit | E12: Communication | F12: 45658 | G12: Cloud | I12: Standard solutions | J12: Secoya A/S, Orbit Online A/S | L12: Secoya A/S | M12: 50-99 | N12: 7-Potential for phase out | O12: 54788 | Q12: Orbit: Orbit is a reporting and analytics solution suitable for businesses of any size. It includes features like automated reporting, report exporting, and interactive dashboards to monitor business metrics and KPIs in real-time | T12: X | U12: Project Sales, replaces Sharepoint 2003 site | V12: =_xlfn.XLOOKUP(Applications[[#This Row],[NoApplication]],#REF!,#REF!,Applications[[#This Row],[Business Owner]],0,1) -> #REF! | AB12: FRFS | AE12: Supply Chain, Project | AI12: Close | AL12: Project-initiated
B13: =_xlfn.CONCAT(Applications[[#This Row],[No]]," - ",Applications[[#This Row],[Application]]) -> 10 - Encryption Key Service (EKS) | C13: 10 | D13: Encryption Key Service (EKS) | E13: Kamstrup - Customer Software | F13: 45658 | I13: Customer Experience | J13: Kamstrup | N13: 3-Kamstrup application | O13: 54788 | Q13: Encryption Key Service (EKS): EKS is a service that provides encryption key management for securing sensitive data. It integrates with various applications to ensure data is encrypted and protected throughout its lifecycle. Consist of many services | V13: =_xlfn.XLOOKUP(Applications[[#This Row],[NoApplication]],#REF!,#REF!,Applications[[#This Row],[Business Owner]],0,1) -> #REF! | AP13: Crown Jewel_1
B14: =_xlfn.CONCAT(Applications[[#This Row],[No]]," - ",Applications[[#This Row],[Application]]) -> 12 - My Kamstrup | C14: 12 | D14: My Kamstrup | E14: Business | F14: 45658 | I14: Customer Experience | J14: Kamstrup | M14: 1000-> | N14: 2-Important application | O14: 54788 | Q14: My Kamstrup: My Kamstrup is a customer portal platform that provides access to various Kamstrup applications and services. It includes features like user administration, encryption key management, subscription management, and case creation | U14: FRFS info from US: MyKamstrup virker ikke ordentligt, aktiveringsmail ryger i spam ofte. Her burde man virkelig ændre på customer experience. | V14: =_xlfn.XLOOKUP(Applications[[#This Row],[NoApplication]],#REF!,#REF!,Applications[[#This Row],[Business Owner]],0,1) -> #REF! | AE14: Sales & Marketing
B15: =_xlfn.CONCAT(Applications[[#This Row],[No]]," - ",Applications[[#This Row],[Application]]) -> 15 - JIRA | C15: 15 | D15: JIRA | E15: Business | F15: 45658 | G15: Cloud | I15: Development Tools | J15: Atlassian | L15: Atlassian, Eficode A/S | M15: 500-999 | N15: 1-Strategic | O15: 54788 | Q15: JIRA: JIRA is a project management and issue-tracking software developed by Atlassian. It is used for bug tracking, issue tracking, and project management, and is widely used by software development teams. | U15: Bitbucket is mostly used for code and code review | V15: =_xlfn.XLOOKUP(Applications[[#This Row],[NoApplication]],#REF!,#REF!,Applications[[#This Row],[Business Owner]],0,1) -> #REF! | AB15: FRFS | AE15: Software, Hardware Departments | AH15: Atlassian | AK15: Strategic decision to use it
B16: =_xlfn.CONCAT(Applications[[#This Row],[No]]," - ",Applications[[#This Row],[Application]]) -> 16 - BitBucket | C16: 16 | D16: BitBucket | E16: Development and Programming | F16: 45658 | G16: Cloud | I16: Development Tools | J16: Atlassian | N16: 5-Investigate | O16: 54788 | Q16: BitBucket: BitBucket is a web-based version control repository hosting service owned by Atlassian. It supports Git and Mercurial version control systems and is used for source code management and collaboration. | S16: LAAG | U16: Jira is used for issue tracking and project management | V16: =_xlfn.XLOOKUP(Applications[[#This Row],[NoApplication]],#REF!,#REF!,Applications[[#This Row],[Business Owner]],0,1) -> #REF! | AH16: Atlassian
B17: =_xlfn.CONCAT(Applications[[#This Row],[No]]," - ",Applications[[#This Row],[Application]]) -> 17 - TFS | C17: 17 | D17: TFS | E17: Development and Programming | F17: 45658 | I17: Development Tools | J17: Microsoft | N17: 5-Investigate | O17: 54788 | Q17: TFS: Team Foundation Server (TFS) is a Microsoft product that provides source code management, project management, and build automation for software development projects. It supports version control, work item tracking, and continuous integration. | V17: =_xlfn.XLOOKUP(Applications[[#This Row],[NoApplication]],#REF!,#REF!,Applications[[#This Row],[Business Owner]],0,1) -> #REF!
B18: =_xlfn.CONCAT(Applications[[#This Row],[No]]," - ",Applications[[#This Row],[Application]]) -> 18 - Microsoft Visual Studio Pro MSDN | C18: 18 | D18: Microsoft Visual Studio Pro MSDN | E18: Development and Programming | F18: 45658 | G18: Distributed Applications | I18: Development Tools | J18: Microsoft | K18: 77D-00111 | M18: 50-99 | N18: 1-Strategic | O18: 54788 | Q18: Microsoft Visual Studio: Microsoft Visual Studio is an integrated development environment (IDE) used for developing applications, websites, and services. It supports various programming languages and includes features like code editing, debugging, and testing. | V18: =_xlfn.XLOOKUP(Applications[[#This Row],[NoApplication]],#REF!,#REF!,Applications[[#This Row],[Business Owner]],0,1) -> #REF! | AB18: Susanne | AD18: IDE | AE18: Software, Hardware Departments | AH18: Microsoft Developper | AJ18: Tolerate/Invest | AK18: Widely used for .NET development
B19: =_xlfn.CONCAT(Applications[[#This Row],[No]]," - ",Applications[[#This Row],[Application]]) -> 19 - TMS | C19: 19 | D19: TMS | E19: Utilities and Miscellaneous | F19: 45658 | I19: ERP Integrated Solutions | J19: Transporeon | N19: 4-Saved for now | O19: 54788 | Q19: TMS: Transportation Management System (TMS) is a software solution that helps organizations manage and optimize their transportation operations. It includes features like route planning, carrier selection, shipment tracking, and freight payment. | S19: KRNO | V19: =_xlfn.XLOOKUP(Applications[[#This Row],[NoApplication]],#REF!,#REF!,Applications[[#This Row],[Business Owner]],0,1) -> #REF! | AE19: Supply Chain
B20: =_xlfn.CONCAT(Applications[[#This Row],[No]]," - ",Applications[[#This Row],[Application]]) -> 21 - Subscription Manager | C20: 21 | D20: Subscription Manager | E20: Utilities and Miscellaneous | F20: 45658 | I20: ERP Integrated Solutions | J20: Flexera Software | N20: 5-Investigate | O20: 54788 | Q20: Subscription Manager: Subscription Manager is a software solution that helps organizations manage their subscription-based services. It includes features like subscription billing, customer management, and analytics. | V20: =_xlfn.XLOOKUP(Applications[[#This Row],[NoApplication]],#REF!,#REF!,Applications[[#This Row],[Business Owner]],0,1) -> #REF!
B21: =_xlfn.CONCAT(Applications[[#This Row],[No]]," - ",Applications[[#This Row],[Application]]) -> 23 - Readsoft | C21: 23 | D21: Readsoft | E21: Business | F21: 45658 | I21: ERP Integrated Solutions | J21: Kofax | M21: 10-49 | N21: 4-Saved for now | O21: 54788 | Q21: Readsoft: Readsoft is a software solution for automating document processing. It includes features like optical character recognition (OCR), data extraction, and workflow automation to streamline document management processes. | V21: =_xlfn.XLOOKUP(Applications[[#This Row],[NoApplication]],#REF!,#REF!,Applications[[#This Row],[Business Owner]],0,1) -> #REF! | AB21: KRTI | AE21: Finans | AI21: Set to Save for now with KRTI
B22: =_xlfn.CONCAT(Applications[[#This Row],[No]]," - ",Applications[[#This Row],[Application]]) -> 24 - Pipechain | C22: 24 | D22: Pipechain | E22: Utilities and Miscellaneous | F22: 45658 | I22: ERP Integrated Solutions | J22: Pipechain, Inc. | N22: 5-Investigate | O22: 54788 | V22: =_xlfn.XLOOKUP(Applications[[#This Row],[NoApplication]],#REF!,#REF!,Applications[[#This Row],[Business Owner]],0,1) -> #REF!
B23: =_xlfn.CONCAT(Applications[[#This Row],[No]]," - ",Applications[[#This Row],[Application]]) -> 25 - PJD 3P | C23: 25 | D23: PJD 3P | E23: Utilities and Miscellaneous | F23: 45658 | I23: Production IT | J23: PJD Group | N23: 5-Investigate | O23: 54788 | V23: =_xlfn.XLOOKUP(Applications[[#This Row],[NoApplication]],#REF!,#REF!,Applications[[#This Row],[Business Owner]],0,1) -> #REF!
B24: =_xlfn.CONCAT(Applications[[#This Row],[No]]," - ",Applications[[#This Row],[Application]]) -> 30 - Billing Com | C24: 30 | D24: Billing Com | E24: Utilities and Miscellaneous | F24: 45658 | I24: Service Tools | J24: Amdocs | N24: 5-Investigate | O24: 54788 | V24: =_xlfn.XLOOKUP(Applications[[#This Row],[NoApplication]],#REF!,#REF!,Applications[[#This Row],[Business Owner]],0,1) -> #REF! | AE24: Supply Chain
B25: =_xlfn.CONCAT(Applications[[#This Row],[No]]," - ",Applications[[#This Row],[Application]]) -> 31 - SIM Service | C25: 31 | D25: SIM Service | E25: Utilities and Miscellaneous | F25: 45658 | I25: Service Tools | J25: SIM Service. | N25: 5-Investigate | O25: 54788 | V25: =_xlfn.XLOOKUP(Applications[[#This Row],[NoApplication]],#REF!,#REF!,Applications[[#This Row],[Business Owner]],0,1) -> #REF!
B26: =_xlfn.CONCAT(Applications[[#This Row],[No]]," - ",Applications[[#This Row],[Application]]) -> 33 - TLF Service | C26: 33 | D26: TLF Service | E26: Utilities and Miscellaneous | F26: 45658 | I26: Service Tools | J26: The Software Vendor for the application TLF Service is TLF Technology. | N26: 5-Investigate | O26: 54788 | V26: =_xlfn.XLOOKUP(Applications[[#This Row],[NoApplication]],#REF!,#REF!,Applications[[#This Row],[Business Owner]],0,1) -> #REF!
B27: =_xlfn.CONCAT(Applications[[#This Row],[No]]," - ",Applications[[#This Row],[Application]]) -> 34 - Custom SIM | C27: 34 | D27: Custom SIM | E27: Utilities and Miscellaneous | F27: 45658 | I27: Service Tools | J27: Custom SIM Technologies | N27: 5-Investigate | O27: 54788 | V27: =_xlfn.XLOOKUP(Applications[[#This Row],[NoApplication]],#REF!,#REF!,Applications[[#This Row],[Business Owner]],0,1) -> #REF!
B28: =_xlfn.CONCAT(Applications[[#This Row],[No]]," - ",Applications[[#This Row],[Application]]) -> 35 - Lessor PM | C28: 35 | D28: Lessor PM | E28: Business | F28: 45658 | G28: Cloud | I28: Other Tools | J28: Lessor PM is developed by Lessor. | N28: 1-Strategic | O28: 54788 | Q28: OBS - High spend - could be renigosiated | S28: HAA | V28: =_xlfn.XLOOKUP(Applications[[#This Row],[NoApplication]],#REF!,#REF!,Applications[[#This Row],[Business Owner]],0,1) -> #REF! | AB28: KRTI | AE28: People | AI28: We are investigating if we can upgrade to LessorLøn - a cloud based replacement from same company (Paychex Europe) | AJ28: Handles all Danish payroll and payslips. | AL28: Project
B29: =_xlfn.CONCAT(Applications[[#This Row],[No]]," - ",Applications[[#This Row],[Application]]) -> 36 - Concur | C29: 36 | D29: Concur | E29: Business | F29: 45658 | G29: Cloud | I29: Other Tools | J29: SAP Concur | M29: 1000-> | N29: 7-Potential for phase out | O29: 54788 | U29: FIN | V29: =_xlfn.XLOOKUP(Applications[[#This Row],[NoApplication]],#REF!,#REF!,Applications[[#This Row],[Business Owner]],0,1) -> #REF! | AB29: KRTI | AE29: Finans | AH29: SAP | AL29: Project
B30: =_xlfn.CONCAT(Applications[[#This Row],[No]]," - ",Applications[[#This Row],[Application]]) -> 37 - OpenLM | C30: 37 | D30: OpenLM | E30: Utilities and Miscellaneous | F30: 45658 | G30: Cloud | I30: Other Tools | J30: OpenLM. | M30: 0-9 | N30: 4-Saved for now | O30: 54788 | Q30: FRFS: Look on if this can be used in general license use in Kamstrup | R30: License Management Services | OpenLM | V30: =_xlfn.XLOOKUP(Applications[[#This Row],[NoApplication]],#REF!,#REF!,Applications[[#This Row],[Business Owner]],0,1) -> #REF! | AE30: Hardware Departments
B31: =_xlfn.CONCAT(Applications[[#This Row],[No]]," - ",Applications[[#This Row],[Application]]) -> 38 - SP TID | C31: 38 | D31: SP TID | E31: Utilities and Miscellaneous | F31: 45658 | I31: Other Tools | J31: SAP | N31: 5-Investigate | O31: 54788 | V31: =_xlfn.XLOOKUP(Applications[[#This Row],[NoApplication]],#REF!,#REF!,Applications[[#This Row],[Business Owner]],0,1) -> #REF!
B32: =_xlfn.CONCAT(Applications[[#This Row],[No]]," - ",Applications[[#This Row],[Application]]) -> 39 - EPOS | C32: 39 | D32: EPOS | E32: Utilities and Miscellaneous | F32: 45658 | I32: Other Tools | J32: NCR Corporation | N32: 5-Investigate | O32: 54788 | V32: =_xlfn.XLOOKUP(Applications[[#This Row],[NoApplication]],#REF!,#REF!,Applications[[#This Row],[Business Owner]],0,1) -> #REF!
B33: =_xlfn.CONCAT(Applications[[#This Row],[No]]," - ",Applications[[#This Row],[Application]]) -> 40 - Omnia | C33: 40 | D33: Omnia | E33: Kamstrup - Customer Software | F33: 45658 | I33: Kamstrup Software | J33: Kamstrup | N33: 3-Kamstrup application | O33: 54788 | Q33: Custom software and hardware solutions | S33: MIA | V33: =_xlfn.XLOOKUP(Applications[[#This Row],[NoApplication]],#REF!,#REF!,Applications[[#This Row],[Business Owner]],0,1) -> #REF! | AE33: Software Departments | AP33: Crown Jewel_1
B34: =_xlfn.CONCAT(Applications[[#This Row],[No]]," - ",Applications[[#This Row],[Application]]) -> 41 - READy | C34: 41 | D34: READy | E34: Kamstrup - Customer Software | F34: 45658 | I34: Kamstrup Software | J34: Kamstrup | N34: 3-Kamstrup application | O34: 54788 | Q34: Visualisation of meters and reading data, heat reports, alarm notification, meter exchange, data export mm. FRFS Rename to READY Manager | S34: JEMR | U34: Remote reading tool for water and heat meters | V34: =_xlfn.XLOOKUP(Applications[[#This Row],[NoApplication]],#REF!,#REF!,Applications[[#This Row],[Business Owner]],0,1) -> #REF! | AE34: Supply Chain | AP34: Crown Jewel_1
B35: =_xlfn.CONCAT(Applications[[#This Row],[No]]," - ",Applications[[#This Row],[Application]]) -> 43 - Ceedling | C35: 43 | D35: Ceedling | E35: Development and Programming | F35: 45658 | G35: Distributed Applications | J35: ThrowTheSwitch, LLC | N35: 2-Important application | O35: 54788 | Q35: Test tool for 'c language' programming. Ceedling is primarily targeted at Test-Driven Development | U35: Test tool (unit test) | V35: =_xlfn.XLOOKUP(Applications[[#This Row],[NoApplication]],#REF!,#REF!,Applications[[#This Row],[Business Owner]],0,1) -> #REF! | W35: RUP | X35: Fra egen afd: JDP,AGR,SAS,TPT,JKI,JML,MTR,RUP,DGG,CKS,KSC,TRL,ACP | Y35: GCC, IAR, (Ruby) | AA35: Opensource | AB35: Opensource | AE35: Hardware Departments | AI35: Test framework for C based tools. | AJ35: Subcomponent for C | AK35: CLI tool used to test C code. | AO35: Investigate
B36: =_xlfn.CONCAT(Applications[[#This Row],[No]]," - ",Applications[[#This Row],[Application]]) -> 44 - C-Spy | C36: 44 | D36: C-Spy | E36: Development and Programming | F36: 45658 | J36: ELM Technology. | N36: 5-Investigate | O36: 54788 | U36: Debugger | V36: =_xlfn.XLOOKUP(Applications[[#This Row],[NoApplication]],#REF!,#REF!,Applications[[#This Row],[Business Owner]],0,1) -> #REF! | W36: KER | X36: Fra egen afd: LTS,JDP,AGR,SAS,TPT,JKI,JML,MTR,RUP,DGG,CKS,KSC,TRL,ACP | Y36: IAR | AA36: IAR | AB36: KER
B37: =_xlfn.CONCAT(Applications[[#This Row],[No]]," - ",Applications[[#This Row],[Application]]) -> 45 - DockLight | C37: 45 | D37: DockLight | E37: Development and Programming | F37: 45658 | G37: Distributed Applications | J37: DockLight Software | N37: 5-Investigate | O37: 54788 | Q37: Docklight is a testing, analysis and simulation tool for serial communication protocols. | U37: Serial script/trace | V37: =_xlfn.XLOOKUP(Applications[[#This Row],[NoApplication]],#REF!,#REF!,Applications[[#This Row],[Business Owner]],0,1) -> #REF! | W37: Ved ikke | X37: Fra egen afd: LTS,JDP,AGR,SAS,TPT,JKI,JML,MTR,RUP,DGG,CKS,KSC,TRL,ACP | AA37: Købt licens + x antal gratis | AB37: Ved ikke | AE37: Hardware Departments | AF37: No | AI37: Test, analysis and simulation tool for hardware. | AJ37: Tolerate | AK37: Investigate usage
B38: =_xlfn.CONCAT(Applications[[#This Row],[No]]," - ",Applications[[#This Row],[Application]]) -> 46 - Doxygen | C38: 46 | D38: Doxygen | E38: Development and Programming | F38: 45658 | J38: Affero, Inc. | N38: 4-Saved for now | O38: 54788 | Q38: dokumentere software ud fra kildekoden | U38: Kodedokumentationsprogram til dokumentation | V38: =_xlfn.XLOOKUP(Applications[[#This Row],[NoApplication]],#REF!,#REF!,Applications[[#This Row],[Business Owner]],0,1) -> #REF! | W38: Ved ikke | X38: Fra egen afd: LTS,JDP,AGR,SAS,TPT,JKI,KKA,BTH,JML,STK,MTR,LAA,ARO,RUP,DGG,CKS,KSC,TRL,ACP; PMB | AA38: Opensource | AB38: Opensource | AE38: Hardware Departments | AI38: Free and automated documentation software. | AJ38: Tolerate/migrate | AK38: Free and open source client system
B39: =_xlfn.CONCAT(Applications[[#This Row],[No]]," - ",Applications[[#This Row],[Application]]) -> 47 - FABric | C39: 47 | D39: FABric | E39: Utilities and Miscellaneous | F39: 45658 | J39: FABric is developed by the company Fabric Software. | N39: 5-Investigate | O39: 54788 | Q39: Fabric is a platform that helps your mobile team build better apps, understand your users, and grow your business. | U39: Python framework - Vedligeholdes internt i R&D | V39: =_xlfn.XLOOKUP(Applications[[#This Row],[NoApplication]],#REF!,#REF!,Applications[[#This Row],[Business Owner]],0,1) -> #REF! | W39: Individuelt pr. bruger | X39: Fra egen afd: LTS,KKA,BTH,STK,MTR,LAA, | AA39: Ved ikke | AB39: Ved ikke
B40: =_xlfn.CONCAT(Applications[[#This Row],[No]]," - ",Applications[[#This Row],[Application]]) -> 48 - FreeRTOS | C40: 48 | D40: FreeRTOS | E40: Development and Programming | F40: 45658 | J40: Amazon Web Services, Inc. | N40: 5-Investigate | O40: 54788 | Q40: MIT Licens, FreeRTOS er blevet porteret til 31 forskellige microcontrollerfamilier, kodning | U40: Development/support to development | V40: =_xlfn.XLOOKUP(Applications[[#This Row],[NoApplication]],#REF!,#REF!,Applications[[#This Row],[Business Owner]],0,1) -> #REF! | W40: Ved ikke | X40: Fra egen afd: JDP,JKI,RUP,DGG,TRL | Y40: IAR, GCC | AA40: Opensource | AB40: Opensource
...

Sheet A-Application_Approval
B1: Chose the application | R1: Auto fill from A-Applications
C2: ECS | F2: Legal
B3: NoApplication | C3: ECS approved | D3: ECS Approval date | E3: ECS Approved by | F3: Legal approved | G3: Legal Approval date | H3: Legal Approved by
B4: kljæk | C4: Yes | D4: 45667 | G4: 45659
B5: øklæø | C5: No | D5: 45672 | G5: 45713
B6: klæj | C6: Under evaluation

Sheet A-Application_Budget
B4: Description | C4: Date | D4: Type | E4: Amount
B5: Azure | C5: 45292 | D5: Budget | E5: 24623000
B6: Licenses | C6: 45292 | D6: Budget | E6: 82277000
B7: Azure | C7: 45291 | D7: Actual | E7: 22385000
B8: Licenses | C8: 45291 | D8: Actual | E8: 52605000
B9: Azure | C9: 45658 | D9: Budget | E9: 36000000
B10: Licenses | C10: 45658 | D10: Budget | E10: 81455000

Sheet B-Business Capability
F2: Level 1 of the business capability | G2: Level 2 of the business capability | H2: Level 3 of the business capability | I2: Gartner Pace Layer strategy as classification. Strategic value for the business | J2: Description of the capability | K2: Value Stream applying to the capability | L2: Value Stream order applying to the Value stream | M2: NIS2 - Criticality | N2: Date of update with business | O2: Initials of business responsabel from the business | P2: Comments
B5: IdLevel123 | C5: Column1 | D5: Type | E5: Level 0 | F5: Level 1 | G5: Level 2 | H5: Level 3 | I5: Pace Layer | J5: Description | K5: Value Stream | L5: Value stream order | M5: NIS2 - Criticality | N5: Updated | O5: Business Responsibel | P5: Comment | Q5: __PowerAppsId__
B6: =_xlfn.CONCAT(Capabilities[[#This Row],[Column1]],"-",Capabilities[[#This Row],[Level 1]],"-",Capabilities[[#This Row],[Level 2]],"-",Capabilities[[#This Row],[Level 3]]) -> 999-All-- | C6: 999 | E6: All | F6: All | K6: N/A | Q6: 21541184-493d-479c-8c0c-6b71625ef1a4
B7: =_xlfn.CONCAT(Capabilities[[#This Row],[Column1]],"-",Capabilities[[#This Row],[Level 1]],"-",Capabilities[[#This Row],[Level 2]],"-",Capabilities[[#This Row],[Level 3]]) -> 1000-Customer Relationship-- | C7: 1000 | D7: BusinessCapability | E7: Sales | F7: Customer Relationship | J7: A robust system designed to manage interactions and relationships with a large customer base effectively and efficiently. | K7: Customer Service and Support | Q7: 1f2d6dcb-b2bf-4dac-92ad-daa3c02c7e9e
B8: =_xlfn.CONCAT(Capabilities[[#This Row],[Column1]],"-",Capabilities[[#This Row],[Level 1]],"-",Capabilities[[#This Row],[Level 2]],"-",Capabilities[[#This Row],[Level 3]]) -> 1008-Customer Relationship-Contact Management- | C8: 1008 | D8: BusinessCapability | E8: Sales | F8: Customer Relationship | G8: Contact Management | J8: Facilitates efficient communication and organization of customer interactions to enhance satisfaction and loyalty. | K8: Customer Service and Support | Q8: e7705fd4-7ec5-4702-8f12-be14c6197fd2
