Workbook

Sheet KamstrupData
B1: Active from date | C1: End date | D1: Chose the capability | E1: Auto fill Level 1 | F1: Auto fill Level 2 | G1: Auto fill Level 3 | H1: Not used | I1: Country code | J1: Business Area using/doing the capability | K1: Department or Team using/doing the capability | L1: Chose the application | M1: Auto fill application | N1: Evaluation of Gartner TIME for the application only in relation to this Capability | O1: Classifications for Business Criticality: Administrative Service Business Operational Business Critical Mission Critical. | P1: Business process applying to the capability | Q1: Value Stream applying to the process and application | R1: Value Stream order | S1: Projects involving the current Capability, Process and Application | T1: Comment reletad to the current row | U1: AUTO CALCULATION | V1: AUTO CALCULATION Link to organisation
B2: Dates | D2: B-Business Capability | I2: O-Organization | L2: A-Applications | P2: C-Business Context | S2: I-Initiative | T2: Comment | U2: Organisation
B4: FromDate | C4: EndDate | D4: IdLevel123 | E4: Capbility level 1 | F4: Capbility level 2 | G4: Capbility level 3 | H4: Capbility level 4 | I4: CountryCode | J4: Business Area | K4: DepartmentTeam | L4: NoApplication | M4: Application | N4: Gartner TIME | O4: Business Criticality | P4: NoProcess | Q4: Value Stream | R4: Value Stream Order | S4: Projects | T4: Comment | U4: ORG_Concat | V4: IdOrg
D5: 999-All-- | E5: =VLOOKUP(D5,'B-Business Capability'!B:H,5,FALSE) -> All | F5: =VLOOKUP(D5,'B-Business Capability'!B:H,6,FALSE) -> 0 | G5: =VLOOKUP(D5,'B-Business Capability'!B:H,7,FALSE) -> 0 | I5: AT10 | J5: All | L5: 299 - Microsoft Teams | M5: =VLOOKUP(L5,'A-Applications'!B:D,3,FALSE) -> Microsoft Teams | N5: Tolerate | O5: Business Operational | P5: P00-All-- | Q5: =VLOOKUP(KamstrupData[[#This Row],[IdLevel123]],'B-Business Capability'!B:L,10,FALSE) -> N/A | R5: =VLOOKUP(KamstrupData[[#This Row],[IdLevel123]],'B-Business Capability'!B:L,11,FALSE) -> 0 | U5: =_xlfn.CONCAT(KamstrupData[[#This Row],[CountryCode]],"_",KamstrupData[[#This Row],[Business Area]],"_",KamstrupData[[#This Row],[DepartmentTeam]]) -> AT10_All_ | V5: =VLOOKUP(KamstrupData[[#This Row],[ORG_Concat]],'O-Organization'!F:H,3,FALSE) -> 11147_AT10_All_All_
D6: 999-All-- | E6: =VLOOKUP(D6,'B-Business Capability'!B:H,5,FALSE) -> All | F6: =VLOOKUP(D6,'B-Business Capability'!B:H,6,FALSE) -> 0 | G6: =VLOOKUP(D6,'B-Business Capability'!B:H,7,FALSE) -> 0 | I6: AT10 | J6: All | L6: 308 - OneDrive | M6: =VLOOKUP(L6,'A-Applications'!B:D,3,FALSE) -> OneDrive | N6: Tolerate | O6: Business Operational | P6: P00-All-- | Q6: =VLOOKUP(KamstrupData[[#This Row],[IdLevel123]],'B-Business Capability'!B:L,10,FALSE) -> N/A | R6: =VLOOKUP(KamstrupData[[#This Row],[IdLevel123]],'B-Business Capability'!B:L,11,FALSE) -> 0 | U6: =_xlfn.CONCAT(KamstrupData[[#This Row],[CountryCode]],"_",KamstrupData[[#This Row],[Business Area]],"_",KamstrupData[[#This Row],[DepartmentTeam]]) -> AT10_All_ | V6: =VLOOKUP(KamstrupData[[#This Row],[ORG_Concat]],'O-Organization'!F:H,3,FALSE) -> 11147_AT10_All_All_
D7: 999-All-- | E7: =VLOOKUP(D7,'B-Business Capability'!B:H,5,FALSE) -> All | F7: =VLOOKUP(D7,'B-Business Capability'!B:H,6,FALSE) -> 0 | G7: =VLOOKUP(D7,'B-Business Capability'!B:H,7,FALSE) -> 0 | I7: AT10 | J7: All | L7: 428 - Microsoft Word | M7: =VLOOKUP(L7,'A-Applications'!B:D,3,FALSE) -> Microsoft Word | N7: Tolerate | O7: Business Operational | P7: P00-All-- | Q7: =VLOOKUP(KamstrupData[[#This Row],[IdLevel123]],'B-Business Capability'!B:L,10,FALSE) -> N/A | R7: =VLOOKUP(KamstrupData[[#This Row],[IdLevel123]],'B-Business Capability'!B:L,11,FALSE) -> 0 | U7: =_xlfn.CONCAT(KamstrupData[[#This Row],[CountryCode]],"_",KamstrupData[[#This Row],[Business Area]],"_",KamstrupData[[#This Row],[DepartmentTeam]]) -> AT10_All_ | V7: =VLOOKUP(KamstrupData[[#This Row],[ORG_Concat]],'O-Organization'!F:H,3,FALSE) -> 11147_AT10_All_All_
D8: 999-All-- | E8: =VLOOKUP(D8,'B-Business Capability'!B:H,5,FALSE) -> All | F8: =VLOOKUP(D8,'B-Business Capability'!B:H,6,FALSE) -> 0 | G8: =VLOOKUP(D8,'B-Business Capability'!B:H,7,FALSE) -> 0 | I8: AT10 | J8: All | L8: 429 - Microsoft Excel | M8: =VLOOKUP(L8,'A-Applications'!B:D,3,FALSE) -> Microsoft Excel | N8: Tolerate | O8: Business Operational | P8: P00-All-- | Q8: =VLOOKUP(KamstrupData[[#This Row],[IdLevel123]],'B-Business Capability'!B:L,10,FALSE) -> N/A | R8: =VLOOKUP(KamstrupData[[#This Row],[IdLevel123]],'B-Business Capability'!B:L,11,FALSE) -> 0 | U8: =_xlfn.CONCAT(KamstrupData[[#This Row],[CountryCode]],"_",KamstrupData[[#This Row],[Business Area]],"_",KamstrupData[[#This Row],[DepartmentTeam]]) -> AT10_All_ | V8: =VLOOKUP(KamstrupData[[#This Row],[ORG_Concat]],'O-Organization'!F:H,3,FALSE) -> 11147_AT10_All_All_
D9: 999-All-- | E9: =VLOOKUP(D9,'B-Business Capability'!B:H,5,FALSE) -> All | F9: =VLOOKUP(D9,'B-Business Capability'!B:H,6,FALSE) -> 0 | G9: =VLOOKUP(D9,'B-Business Capability'!B:H,7,FALSE) -> 0 | I9: AT10 | J9: All | L9: 430 - Microsoft Power Point | M9: =VLOOKUP(L9,'A-Applications'!B:D,3,FALSE) -> Microsoft Power Point | N9: Tolerate | O9: Business Operational | P9: P00-All-- | Q9: =VLOOKUP(KamstrupData[[#This Row],[IdLevel123]],'B-Business Capability'!B:L,10,FALSE) -> N/A | R9: =VLOOKUP(KamstrupData[[#This Row],[IdLevel123]],'B-Business Capability'!B:L,11,FALSE) -> 0 | U9: =_xlfn.CONCAT(KamstrupData[[#This Row],[CountryCode]],"_",KamstrupData[[#This Row],[Business Area]],"_",KamstrupData[[#This Row],[DepartmentTeam]]) -> AT10_All_ | V9: =VLOOKUP(KamstrupData[[#This Row],[ORG_Concat]],'O-Organization'!F:H,3,FALSE) -> 11147_AT10_All_All_
D10: 999-All-- | E10: =VLOOKUP(D10,'B-Business Capability'!B:H,5,FALSE) -> All | F10: =VLOOKUP(D10,'B-Business Capability'!B:H,6,FALSE) -> 0 | G10: =VLOOKUP(D10,'B-Business Capability'!B:H,7,FALSE) -> 0 | I10: AT10 | J10: All | L10: 431 - Microsoft Outlook | M10: =VLOOKUP(L10,'A-Applications'!B:D,3,FALSE) -> Microsoft Outlook | N10: Tolerate | O10: Business Operational | P10: P00-All-- | Q10: =VLOOKUP(KamstrupData[[#This Row],[IdLevel123]],'B-Business Capability'!B:L,10,FALSE) -> N/A | R10: =VLOOKUP(KamstrupData[[#This Row],[IdLevel123]],'B-Business Capability'!B:L,11,FALSE) -> 0 | U10: =_xlfn.CONCAT(KamstrupData[[#This Row],[CountryCode]],"_",KamstrupData[[#This Row],[Business Area]],"_",KamstrupData[[#This Row],[DepartmentTeam]]) -> AT10_All_ | V10: =VLOOKUP(KamstrupData[[#This Row],[ORG_Concat]],'O-Organization'!F:H,3,FALSE) -> 11147_AT10_All_All_
D11: 999-All-- | E11: =VLOOKUP(D11,'B-Business Capability'!B:H,5,FALSE) -> All | F11: =VLOOKUP(D11,'B-Business Capability'!B:H,6,FALSE) -> 0 | G11: =VLOOKUP(D11,'B-Business Capability'!B:H,7,FALSE) -> 0 | I11: AT10 | J11: All | L11: 483 - Microsoft OneNote | M11: =VLOOKUP(L11,'A-Applications'!B:D,3,FALSE) -> Microsoft OneNote | N11: Tolerate | O11: Administrative Service | P11: P00-All-- | Q11: =VLOOKUP(KamstrupData[[#This Row],[IdLevel123]],'B-Business Capability'!B:L,10,FALSE) -> N/A | R11: =VLOOKUP(KamstrupData[[#This Row],[IdLevel123]],'B-Business Capability'!B:L,11,FALSE) -> 0 | U11: =_xlfn.CONCAT(KamstrupData[[#This Row],[CountryCode]],"_",KamstrupData[[#This Row],[Business Area]],"_",KamstrupData[[#This Row],[DepartmentTeam]]) -> AT10_All_ | V11: =VLOOKUP(KamstrupData[[#This Row],[ORG_Concat]],'O-Organization'!F:H,3,FALSE) -> 11147_AT10_All_All_
D12: 1132-Finance-Financial Planning & Analysis-Cost Accounting_Plan | E12: =VLOOKUP(D12,'B-Business Capability'!B:H,5,FALSE) -> Finance | F12: =VLOOKUP(D12,'B-Business Capability'!B:H,6,FALSE) -> Financial Planning & Analysis | G12: =VLOOKUP(D12,'B-Business Capability'!B:H,7,FALSE) -> Cost Accounting_Plan | I12: AT10 | J12: AT_Customer Service | L12: 1 - IFS ERP | M12: =VLOOKUP(L12,'A-Applications'!B:D,3,FALSE) -> IFS ERP | N12: Tolerate | O12: Business Critical | P12: P18-Budget-- | Q12: =VLOOKUP(KamstrupData[[#This Row],[IdLevel123]],'B-Business Capability'!B:L,10,FALSE) -> N/A | R12: =VLOOKUP(KamstrupData[[#This Row],[IdLevel123]],'B-Business Capability'!B:L,11,FALSE) -> 0 | U12: =_xlfn.CONCAT(KamstrupData[[#This Row],[CountryCode]],"_",KamstrupData[[#This Row],[Business Area]],"_",KamstrupData[[#This Row],[DepartmentTeam]]) -> AT10_AT_Customer Service_ | V12: =VLOOKUP(KamstrupData[[#This Row],[ORG_Concat]],'O-Organization'!F:H,3,FALSE) -> 11025_AT10_Customer Service_AT_Customer Service_
D13: 1137-Finance-Settlements & Payments-Account Payables | E13: =VLOOKUP(D13,'B-Business Capability'!B:H,5,FALSE) -> Finance | F13: =VLOOKUP(D13,'B-Business Capability'!B:H,6,FALSE) -> Settlements & Payments | G13: =VLOOKUP(D13,'B-Business Capability'!B:H,7,FALSE) -> Account Payables | I13: AT10 | J13: AT_Finance | L13: 1 - IFS ERP | M13: =VLOOKUP(L13,'A-Applications'!B:D,3,FALSE) -> IFS ERP | N13: Tolerate | O13: Administrative Service | P13: P14-Accounting-SP14.1-Procure to Pay | Q13: =VLOOKUP(KamstrupData[[#This Row],[IdLevel123]],'B-Business Capability'!B:L,10,FALSE) -> Procure-to-Pay (P2P) | R13: =VLOOKUP(KamstrupData[[#This Row],[IdLevel123]],'B-Business Capability'!B:L,11,FALSE) -> 500 | U13: =_xlfn.CONCAT(KamstrupData[[#This Row],[CountryCode]],"_",KamstrupData[[#This Row],[Business Area]],"_",KamstrupData[[#This Row],[DepartmentTeam]]) -> AT10_AT_Finance_ | V13: =VLOOKUP(KamstrupData[[#This Row],[ORG_Concat]],'O-Organization'!F:H,3,FALSE) -> 11063_AT10_Finance_AT_Finance_
D14: 1137-Finance-Settlements & Payments-Account Payables | E14: =VLOOKUP(D14,'B-Business Capability'!B:H,5,FALSE) -> Finance | F14: =VLOOKUP(D14,'B-Business Capability'!B:H,6,FALSE) -> Settlements & Payments | G14: =VLOOKUP(D14,'B-Business Capability'!B:H,7,FALSE) -> Account Payables | I14: AT10 | J14: AT_Finance | L14: 443 - VIES | M14: =VLOOKUP(L14,'A-Applications'!B:D,3,FALSE) -> VIES | N14: Tolerate | P14: P14-Accounting-SP14.1-Procure to Pay | Q14: =VLOOKUP(KamstrupData[[#This Row],[IdLevel123]],'B-Business Capability'!B:L,10,FALSE) -> Procure-to-Pay (P2P) | R14: =VLOOKUP(KamstrupData[[#This Row],[IdLevel123]],'B-Business Capability'!B:L,11,FALSE) -> 500 | U14: =_xlfn.CONCAT(KamstrupData[[#This Row],[CountryCode]],"_",KamstrupData[[#This Row],[Business Area]],"_",KamstrupData[[#This Row],[DepartmentTeam]]) -> AT10_AT_Finance_ | V14: =VLOOKUP(KamstrupData[[#This Row],[ORG_Concat]],'O-Organization'!F:H,3,FALSE) -> 11063_AT10_Finance_AT_Finance_
D15: 3097-Finance-Accounting-Accounts Recievabel | E15: =VLOOKUP(D15,'B-Business Capability'!B:H,5,FALSE) -> Finance | F15: =VLOOKUP(D15,'B-Business Capability'!B:H,6,FALSE) -> Accounting | G15: =VLOOKUP(D15,'B-Business Capability'!B:H,7,FALSE) -> Accounts Recievabel | I15: AT10 | J15: AT_Finance | L15: 443 - VIES | M15: =VLOOKUP(L15,'A-Applications'!B:D,3,FALSE) -> VIES | N15: Tolerate | P15: P14-Accounting-SP14.2-Order to Cash | Q15: =VLOOKUP(KamstrupData[[#This Row],[IdLevel123]],'B-Business Capability'!B:L,10,FALSE) -> N/A | R15: =VLOOKUP(KamstrupData[[#This Row],[IdLevel123]],'B-Business Capability'!B:L,11,FALSE) -> 0 | U15: =_xlfn.CONCAT(KamstrupData[[#This Row],[CountryCode]],"_",KamstrupData[[#This Row],[Business Area]],"_",KamstrupData[[#This Row],[DepartmentTeam]]) -> AT10_AT_Finance_ | V15: =VLOOKUP(KamstrupData[[#This Row],[ORG_Concat]],'O-Organization'!F:H,3,FALSE) -> 11063_AT10_Finance_AT_Finance_
D16: 1291-Strategic Management-Manage Core Business-Manage Projects | E16: =VLOOKUP(D16,'B-Business Capability'!B:H,5,FALSE) -> Strategic Management | F16: =VLOOKUP(D16,'B-Business Capability'!B:H,6,FALSE) -> Manage Core Business | G16: =VLOOKUP(D16,'B-Business Capability'!B:H,7,FALSE) -> Manage Projects | I16: AT10 | J16: AT_Customer Service | L16: 1 - IFS ERP | M16: =VLOOKUP(L16,'A-Applications'!B:D,3,FALSE) -> IFS ERP | N16: Tolerate | O16: Business Critical | P16: P12-Customer Solution Deployment-- | Q16: =VLOOKUP(KamstrupData[[#This Row],[IdLevel123]],'B-Business Capability'!B:L,10,FALSE) -> N/A | R16: =VLOOKUP(KamstrupData[[#This Row],[IdLevel123]],'B-Business Capability'!B:L,11,FALSE) -> 0 | U16: =_xlfn.CONCAT(KamstrupData[[#This Row],[CountryCode]],"_",KamstrupData[[#This Row],[Business Area]],"_",KamstrupData[[#This Row],[DepartmentTeam]]) -> AT10_AT_Customer Service_ | V16: =VLOOKUP(KamstrupData[[#This Row],[ORG_Concat]],'O-Organization'!F:H,3,FALSE) -> 11025_AT10_Customer Service_AT_Customer Service_
D17: 3028-Sales-Sales Operations-Claims, returns and Refund management | E17: =VLOOKUP(D17,'B-Business Capability'!B:H,5,FALSE) -> Sales | F17: =VLOOKUP(D17,'B-Business Capability'!B:H,6,FALSE) -> Sales Operations | G17: =VLOOKUP(D17,'B-Business Capability'!B:H,7,FALSE) -> Claims, returns and Refund management | I17: AT10 | J17: AT_Customer Service | L17: 1 - IFS ERP | M17: =VLOOKUP(L17,'A-Applications'!B:D,3,FALSE) -> IFS ERP | N17: Tolerate | O17: Business Critical | P17: P-Not mapped to process-- | Q17: =VLOOKUP(KamstrupData[[#This Row],[IdLevel123]],'B-Business Capability'!B:L,10,FALSE) -> Order-to-Cash (O2C) | R17: =VLOOKUP(KamstrupData[[#This Row],[IdLevel123]],'B-Business Capability'!B:L,11,FALSE) -> 600 | U17: =_xlfn.CONCAT(KamstrupData[[#This Row],[CountryCode]],"_",KamstrupData[[#This Row],[Business Area]],"_",KamstrupData[[#This Row],[DepartmentTeam]]) -> AT10_AT_Customer Service_ | V17: =VLOOKUP(KamstrupData[[#This Row],[ORG_Concat]],'O-Organization'!F:H,3,FALSE) -> 11025_AT10_Customer Service_AT_Customer Service_
D18: 4203-Customer Service-Customer Service and Support-Service Request Management | E18: =VLOOKUP(D18,'B-Business Capability'!B:H,5,FALSE) -> Customer Service | F18: =VLOOKUP(D18,'B-Business Capability'!B:H,6,FALSE) -> Customer Service and Support | G18: =VLOOKUP(D18,'B-Business Capability'!B:H,7,FALSE) -> Service Request Management | I18: AT10 | J18: AT_Customer Service | L18: 1 - IFS ERP | M18: =VLOOKUP(L18,'A-Applications'!B:D,3,FALSE) -> IFS ERP | N18: Tolerate | O18: Business Critical | P18: P13-Customer Service & Operation-- | Q18: =VLOOKUP(KamstrupData[[#This Row],[IdLevel123]],'B-Business Capability'!B:L,10,FALSE) -> Customer Service and Support | R18: =VLOOKUP(KamstrupData[[#This Row],[IdLevel123]],'B-Business Capability'!B:L,11,FALSE) -> 0 | U18: =_xlfn.CONCAT(KamstrupData[[#This Row],[CountryCode]],"_",KamstrupData[[#This Row],[Business Area]],"_",KamstrupData[[#This Row],[DepartmentTeam]]) -> AT10_AT_Customer Service_ | V18: =VLOOKUP(KamstrupData[[#This Row],[ORG_Concat]],'O-Organization'!F:H,3,FALSE) -> 11025_AT10_Customer Service_AT_Customer Service_
D19: 4207-Customer Service-Customer Service and Support-Customer Warranty Claim Processing | E19: =VLOOKUP(D19,'B-Business Capability'!B:H,5,FALSE) -> Customer Service | F19: =VLOOKUP(D19,'B-Business Capability'!B:H,6,FALSE) -> Customer Service and Support | G19: =VLOOKUP(D19,'B-Business Capability'!B:H,7,FALSE) -> Customer Warranty Claim Processing | I19: AT10 | J19: AT_Customer Service | L19: 1 - IFS ERP | M19: =VLOOKUP(L19,'A-Applications'!B:D,3,FALSE) -> IFS ERP | N19: Tolerate | O19: Business Critical | P19: P13-Customer Service & Operation-- | Q19: =VLOOKUP(KamstrupData[[#This Row],[IdLevel123]],'B-Business Capability'!B:L,10,FALSE) -> Customer Service and Support | R19: =VLOOKUP(KamstrupData[[#This Row],[IdLevel123]],'B-Business Capability'!B:L,11,FALSE) -> 0 | U19: =_xlfn.CONCAT(KamstrupData[[#This Row],[CountryCode]],"_",KamstrupData[[#This Row],[Business Area]],"_",KamstrupData[[#This Row],[DepartmentTeam]]) -> AT10_AT_Customer Service_ | V19: =VLOOKUP(KamstrupData[[#This Row],[ORG_Concat]],'O-Organization'!F:H,3,FALSE) -> 11025_AT10_Customer Service_AT_Customer Service_
D20: 4231-Customer Service-Customer Project Management-Ressource Management | E20: =VLOOKUP(D20,'B-Business Capability'!B:H,5,FALSE) -> Customer Service | F20: =VLOOKUP(D20,'B-Business Capability'!B:H,6,FALSE) -> Customer Project Management | G20: =VLOOKUP(D20,'B-Business Capability'!B:H,7,FALSE) -> Ressource Management | I20: AT10 | J20: AT_Customer Service | L20: 1 - IFS ERP | M20: =VLOOKUP(L20,'A-Applications'!B:D,3,FALSE) -> IFS ERP | N20: Tolerate | O20: Business Critical | P20: P12-Customer Solution Deployment-- | Q20: =VLOOKUP(KamstrupData[[#This Row],[IdLevel123]],'B-Business Capability'!B:L,10,FALSE) -> Order-to-Cash (O2C) | R20: =VLOOKUP(KamstrupData[[#This Row],[IdLevel123]],'B-Business Capability'!B:L,11,FALSE) -> 0 | U20: =_xlfn.CONCAT(KamstrupData[[#This Row],[CountryCode]],"_",KamstrupData[[#This Row],[Business Area]],"_",KamstrupData[[#This Row],[DepartmentTeam]]) -> AT10_AT_Customer Service_ | V20: =VLOOKUP(KamstrupData[[#This Row],[ORG_Concat]],'O-Organization'!F:H,3,FALSE) -> 11025_AT10_Customer Service_AT_Customer Service_
D21: 4231-Customer Service-Customer Project Management-Ressource Management | E21: =VLOOKUP(D21,'B-Business Capability'!B:H,5,FALSE) -> Customer Service | F21: =VLOOKUP(D21,'B-Business Capability'!B:H,6,FALSE) -> Customer Project Management | G21: =VLOOKUP(D21,'B-Business Capability'!B:H,7,FALSE) -> Ressource Management | I21: AT10 | J21: AT_Customer Service | L21: 1 - IFS ERP | M21: =VLOOKUP(L21,'A-Applications'!B:D,3,FALSE) -> IFS ERP | N21: Tolerate | O21: Business Operational | P21: P12-Customer Solution Deployment-- | Q21: =VLOOKUP(KamstrupData[[#This Row],[IdLevel123]],'B-Business Capability'!B:L,10,FALSE) -> Order-to-Cash (O2C) | R21: =VLOOKUP(KamstrupData[[#This Row],[IdLevel123]],'B-Business Capability'!B:L,11,FALSE) -> 0 | U21: =_xlfn.CONCAT(KamstrupData[[#This Row],[CountryCode]],"_",KamstrupData[[#This Row],[Business Area]],"_",KamstrupData[[#This Row],[DepartmentTeam]]) -> AT10_AT_Customer Service_ | V21: =VLOOKUP(KamstrupData[[#This Row],[ORG_Concat]],'O-Organization'!F:H,3,FALSE) -> 11025_AT10_Customer Service_AT_Customer Service_
D22: 4232-Customer Service-Customer Project Management-Financial Analytics and Management | E22: =VLOOKUP(D22,'B-Business Capability'!B:H,5,FALSE) -> Customer Service | F22: =VLOOKUP(D22,'B-Business Capability'!B:H,6,FALSE) -> Customer Project Management | G22: =VLOOKUP(D22,'B-Business Capability'!B:H,7,FALSE) -> Financial Analytics and Management | I22: AT10 | J22: AT_Customer Service | L22: 1 - IFS ERP | M22: =VLOOKUP(L22,'A-Applications'!B:D,3,FALSE) -> IFS ERP | N22: Tolerate | O22: Business Critical | P22: P12-Customer Solution Deployment-- | Q22: =VLOOKUP(KamstrupData[[#This Row],[IdLevel123]],'B-Business Capability'!B:L,10,FALSE) -> Order-to-Cash (O2C) | R22: =VLOOKUP(KamstrupData[[#This Row],[IdLevel123]],'B-Business Capability'!B:L,11,FALSE) -> 0 | U22: =_xlfn.CONCAT(KamstrupData[[#This Row],[CountryCode]],"_",KamstrupData[[#This Row],[Business Area]],"_",KamstrupData[[#This Row],[DepartmentTeam]]) -> AT10_AT_Customer Service_ | V22: =VLOOKUP(KamstrupData[[#This Row],[ORG_Concat]],'O-Organization'!F:H,3,FALSE) -> 11025_AT10_Customer Service_AT_Customer Service_
D23: 4232-Customer Service-Customer Project Management-Financial Analytics and Management | E23: =VLOOKUP(D23,'B-Business Capability'!B:H,5,FALSE) -> Customer Service | F23: =VLOOKUP(D23,'B-Business Capability'!B:H,6,FALSE) -> Customer Project Management | G23: =VLOOKUP(D23,'B-Business Capability'!B:H,7,FALSE) -> Financial Analytics and Management | I23: AT10 | J23: AT_Customer Service | L23: 1 - IFS ERP | M23: =VLOOKUP(L23,'A-Applications'!B:D,3,FALSE) -> IFS ERP | N23: Tolerate | O23: Business Operational | P23: P12-Customer Solution Deployment-- | Q23: =VLOOKUP(KamstrupData[[#This Row],[IdLevel123]],'B-Business Capability'!B:L,10,FALSE) -> Order-to-Cash (O2C) | R23: =VLOOKUP(KamstrupData[[#This Row],[IdLevel123]],'B-Business Capability'!B:L,11,FALSE) -> 0 | U23: =_xlfn.CONCAT(KamstrupData[[#This Row],[CountryCode]],"_",KamstrupData[[#This Row],[Business Area]],"_",KamstrupData[[#This Row],[DepartmentTeam]]) -> AT10_AT_Customer Service_ | V23: =VLOOKUP(KamstrupData[[#This Row],[ORG_Concat]],'O-Organization'!F:H,3,FALSE) -> 11025_AT10_Customer Service_AT_Customer Service_
D24: 4203-Customer Service-Customer Service and Support-Service Request Management | E24: =VLOOKUP(D24,'B-Business Capability'!B:H,5,FALSE) -> Customer Service | F24: =VLOOKUP(D24,'B-Business Capability'!B:H,6,FALSE) -> Customer Service and Support | G24: =VLOOKUP(D24,'B-Business Capability'!B:H,7,FALSE) -> Service Request Management | I24: AT10 | J24: AT_Customer Service | L24: 10 - Encryption Key Service (EKS) | M24: =VLOOKUP(L24,'A-Applications'!B:D,3,FALSE) -> Encryption Key Service (EKS) | N24: Tolerate | O24: Business Critical | P24: P13-Customer Service & Operation-- | Q24: =VLOOKUP(KamstrupData[[#This Row],[IdLevel123]],'B-Business Capability'!B:L,10,FALSE) -> Customer Service and Support | R24: =VLOOKUP(KamstrupData[[#This Row],[IdLevel123]],'B-Business Capability'!B:L,11,FALSE) -> 0 | U24: =_xlfn.CONCAT(KamstrupData[[#This Row],[CountryCode]],"_",KamstrupData[[#This Row],[Business Area]],"_",KamstrupData[[#This Row],[DepartmentTeam]]) -> AT10_AT_Customer Service_ | V24: =VLOOKUP(KamstrupData[[#This Row],[ORG_Concat]],'O-Organization'!F:H,3,FALSE) -> 11025_AT10_Customer Service_AT_Customer Service_
D25: 4709-OT Hosting-OT Operations & Service- | E25: =VLOOKUP(D25,'B-Business Capability'!B:H,5,FALSE) -> OT Hosting | F25: =VLOOKUP(D25,'B-Business Capability'!B:H,6,FALSE) -> OT Operations & Service | G25: =VLOOKUP(D25,'B-Business Capability'!B:H,7,FALSE) -> 0 | I25: AT10 | J25: AT_Customer Service | L25: 10 - Encryption Key Service (EKS) | M25: =VLOOKUP(L25,'A-Applications'!B:D,3,FALSE) -> Encryption Key Service (EKS) | N25: Tolerate | O25: Business Critical | P25: P13-Customer Service & Operation-- | Q25: =VLOOKUP(KamstrupData[[#This Row],[IdLevel123]],'B-Business Capability'!B:L,10,FALSE) -> N/A | R25: =VLOOKUP(KamstrupData[[#This Row],[IdLevel123]],'B-Business Capability'!B:L,11,FALSE) -> 0 | U25: =_xlfn.CONCAT(KamstrupData[[#This Row],[CountryCode]],"_",KamstrupData[[#This Row],[Business Area]],"_",KamstrupData[[#This Row],[DepartmentTeam]]) -> AT10_AT_Customer Service_ | V25: =VLOOKUP(KamstrupData[[#This Row],[ORG_Concat]],'O-Organization'!F:H,3,FALSE) -> 11025_AT10_Customer Service_AT_Customer Service_
D26: 4203-Customer Service-Customer Service and Support-Service Request Management | E26: =VLOOKUP(D26,'B-Business Capability'!B:H,5,FALSE) -> Customer Service | F26: =VLOOKUP(D26,'B-Business Capability'!B:H,6,FALSE) -> Customer Service and Support | G26: =VLOOKUP(D26,'B-Business Capability'!B:H,7,FALSE) -> Service Request Management | I26: AT10 | J26: AT_Customer Service | L26: 1011 - Metertool OMNIA | M26: =VLOOKUP(L26,'A-Applications'!B:D,3,FALSE) -> Metertool OMNIA | N26: Tolerate | O26: Business Operational | P26: P13-Customer Service & Operation-- | Q26: =VLOOKUP(KamstrupData[[#This Row],[IdLevel123]],'B-Business Capability'!B:L,10,FALSE) -> Customer Service and Support | R26: =VLOOKUP(KamstrupData[[#This Row],[IdLevel123]],'B-Business Capability'!B:L,11,FALSE) -> 0 | U26: =_xlfn.CONCAT(KamstrupData[[#This Row],[CountryCode]],"_",KamstrupData[[#This Row],[Business Area]],"_",KamstrupData[[#This Row],[DepartmentTeam]]) -> AT10_AT_Customer Service_ | V26: =VLOOKUP(KamstrupData[[#This Row],[ORG_Concat]],'O-Organization'!F:H,3,FALSE) -> 11025_AT10_Customer Service_AT_Customer Service_
D27: 4203-Customer Service-Customer Service and Support-Service Request Management | E27: =VLOOKUP(D27,'B-Business Capability'!B:H,5,FALSE) -> Customer Service | F27: =VLOOKUP(D27,'B-Business Capability'!B:H,6,FALSE) -> Customer Service and Support | G27: =VLOOKUP(D27,'B-Business Capability'!B:H,7,FALSE) -> Service Request Management | I27: AT10 | J27: AT_Customer Service | L27: 1012 - Glogg | M27: =VLOOKUP(L27,'A-Applications'!B:D,3,FALSE) -> Glogg | P27: P13-Customer Service & Operation-- | Q27: =VLOOKUP(KamstrupData[[#This Row],[IdLevel123]],'B-Business Capability'!B:L,10,FALSE) -> Customer Service and Support | R27: =VLOOKUP(KamstrupData[[#This Row],[IdLevel123]],'B-Business Capability'!B:L,11,FALSE) -> 0 | U27: =_xlfn.CONCAT(KamstrupData[[#This Row],[CountryCode]],"_",KamstrupData[[#This Row],[Business Area]],"_",KamstrupData[[#This Row],[DepartmentTeam]]) -> AT10_AT_Customer Service_ | V27: =VLOOKUP(KamstrupData[[#This Row],[ORG_Concat]],'O-Organization'!F:H,3,FALSE) -> 11025_AT10_Customer Service_AT_Customer Service_
D28: 4203-Customer Service-Customer Service and Support-Service Request Management | E28: =VLOOKUP(D28,'B-Business Capability'!B:H,5,FALSE) -> Customer Service | F28: =VLOOKUP(D28,'B-Business Capability'!B:H,6,FALSE) -> Customer Service and Support | G28: =VLOOKUP(D28,'B-Business Capability'!B:H,7,FALSE) -> Service Request Management | I28: AT10 | J28: AT_Customer Service | L28: 1042 - check.kamstrup.com(concentratorLog) | M28: =VLOOKUP(L28,'A-Applications'!B:D,3,FALSE) -> check.kamstrup.com(concentratorLog) | N28: Tolerate | O28: Business Operational | P28: P13-Customer Service & Operation-- | Q28: =VLOOKUP(KamstrupData[[#This Row],[IdLevel123]],'B-Business Capability'!B:L,10,FALSE) -> Customer Service and Support | R28: =VLOOKUP(KamstrupData[[#This Row],[IdLevel123]],'B-Business Capability'!B:L,11,FALSE) -> 0 | U28: =_xlfn.CONCAT(KamstrupData[[#This Row],[CountryCode]],"_",KamstrupData[[#This Row],[Business Area]],"_",KamstrupData[[#This Row],[DepartmentTeam]]) -> AT10_AT_Customer Service_ | V28: =VLOOKUP(KamstrupData[[#This Row],[ORG_Concat]],'O-Organization'!F:H,3,FALSE) -> 11025_AT10_Customer Service_AT_Customer Service_
D29: 4233-Customer Service-Customer Project Management-Project Management | E29: =VLOOKUP(D29,'B-Business Capability'!B:H,5,FALSE) -> Customer Service | F29: =VLOOKUP(D29,'B-Business Capability'!B:H,6,FALSE) -> Customer Project Management | G29: =VLOOKUP(D29,'B-Business Capability'!B:H,7,FALSE) -> Project Management | I29: AT10 | J29: AT_Customer Service | L29: 1042 - check.kamstrup.com(concentratorLog) | M29: =VLOOKUP(L29,'A-Applications'!B:D,3,FALSE) -> check.kamstrup.com(concentratorLog) | N29: Tolerate | O29: Business Operational | P29: P12-Customer Solution Deployment-- | Q29: =VLOOKUP(KamstrupData[[#This Row],[IdLevel123]],'B-Business Capability'!B:L,10,FALSE) -> Order-to-Cash (O2C) | R29: =VLOOKUP(KamstrupData[[#This Row],[IdLevel123]],'B-Business Capability'!B:L,11,FALSE) -> 0 | U29: =_xlfn.CONCAT(KamstrupData[[#This Row],[CountryCode]],"_",KamstrupData[[#This Row],[Business Area]],"_",KamstrupData[[#This Row],[DepartmentTeam]]) -> AT10_AT_Customer Service_ | V29: =VLOOKUP(KamstrupData[[#This Row],[ORG_Concat]],'O-Organization'!F:H,3,FALSE) -> 11025_AT10_Customer Service_AT_Customer Service_
D30: 4203-Customer Service-Customer Service and Support-Service Request Management | E30: =VLOOKUP(D30,'B-Business Capability'!B:H,5,FALSE) -> Customer Service | F30: =VLOOKUP(D30,'B-Business Capability'!B:H,6,FALSE) -> Customer Service and Support | G30: =VLOOKUP(D30,'B-Business Capability'!B:H,7,FALSE) -> Service Request Management | I30: AT10 | J30: AT_Customer Service | L30: 1043 - Kamstrup ALD | M30: =VLOOKUP(L30,'A-Applications'!B:D,3,FALSE) -> Kamstrup ALD | N30: Tolerate | O30: Business Operational | P30: P13-Customer Service & Operation-- | Q30: =VLOOKUP(KamstrupData[[#This Row],[IdLevel123]],'B-Business Capability'!B:L,10,FALSE) -> Customer Service and Support | R30: =VLOOKUP(KamstrupData[[#This Row],[IdLevel123]],'B-Business Capability'!B:L,11,FALSE) -> 0 | U30: =_xlfn.CONCAT(KamstrupData[[#This Row],[CountryCode]],"_",KamstrupData[[#This Row],[Business Area]],"_",KamstrupData[[#This Row],[DepartmentTeam]]) -> AT10_AT_Customer Service_ | V30: =VLOOKUP(KamstrupData[[#This Row],[ORG_Concat]],'O-Organization'!F:H,3,FALSE) -> 11025_AT10_Customer Service_AT_Customer Service_
D31: 4233-Customer Service-Customer Project Management-Project Management | E31: =VLOOKUP(D31,'B-Business Capability'!B:H,5,FALSE) -> Customer Service | F31: =VLOOKUP(D31,'B-Business Capability'!B:H,6,FALSE) -> Customer Project Management | G31: =VLOOKUP(D31,'B-Business Capability'!B:H,7,FALSE) -> Project Management | I31: AT10 | J31: AT_Customer Service | L31: 1043 - Kamstrup ALD | M31: =VLOOKUP(L31,'A-Applications'!B:D,3,FALSE) -> Kamstrup ALD | N31: Tolerate | O31: Business Operational | P31: P12-Customer Solution Deployment-- | Q31: =VLOOKUP(KamstrupData[[#This Row],[IdLevel123]],'B-Business Capability'!B:L,10,FALSE) -> Order-to-Cash (O2C) | R31: =VLOOKUP(KamstrupData[[#This Row],[IdLevel123]],'B-Business Capability'!B:L,11,FALSE) -> 0 | U31: =_xlfn.CONCAT(KamstrupData[[#This Row],[CountryCode]],"_",KamstrupData[[#This Row],[Business Area]],"_",KamstrupData[[#This Row],[DepartmentTeam]]) -> AT10_AT_Customer Service_ | V31: =VLOOKUP(KamstrupData[[#This Row],[ORG_Concat]],'O-Organization'!F:H,3,FALSE) -> 11025_AT10_Customer Service_AT_Customer Service_
D32: 4201-Customer Service-Customer Service and Support- | E32: =VLOOKUP(D32,'B-Business Capability'!B:H,5,FALSE) -> Customer Service | F32: =VLOOKUP(D32,'B-Business Capability'!B:H,6,FALSE) -> Customer Service and Support | G32: =VLOOKUP(D32,'B-Business Capability'!B:H,7,FALSE) -> 0 | I32: AT10 | J32: AT_Customer Service | L32: 1059 - flonidan | M32: =VLOOKUP(L32,'A-Applications'!B:D,3,FALSE) -> flonidan | P32: P13-Customer Service & Operation-- | Q32: =VLOOKUP(KamstrupData[[#This Row],[IdLevel123]],'B-Business Capability'!B:L,10,FALSE) -> Customer Service and Support | R32: =VLOOKUP(KamstrupData[[#This Row],[IdLevel123]],'B-Business Capability'!B:L,11,FALSE) -> 0 | U32: =_xlfn.CONCAT(KamstrupData[[#This Row],[CountryCode]],"_",KamstrupData[[#This Row],[Business Area]],"_",KamstrupData[[#This Row],[DepartmentTeam]]) -> AT10_AT_Customer Service_ | V32: =VLOOKUP(KamstrupData[[#This Row],[ORG_Concat]],'O-Organization'!F:H,3,FALSE) -> 11025_AT10_Customer Service_AT_Customer Service_
D33: 4209-Customer Service-Customer Service and Support-Omnichannel Customer Engagement | E33: =VLOOKUP(D33,'B-Business Capability'!B:H,5,FALSE) -> Customer Service | F33: =VLOOKUP(D33,'B-Business Capability'!B:H,6,FALSE) -> Customer Service and Support | G33: =VLOOKUP(D33,'B-Business Capability'!B:H,7,FALSE) -> Omnichannel Customer Engagement | I33: AT10 | J33: AT_Customer Service | L33: 12 - My Kamstrup | M33: =VLOOKUP(L33,'A-Applications'!B:D,3,FALSE) -> My Kamstrup | N33: Tolerate | O33: Business Critical | P33: P13-Customer Service & Operation-- | Q33: =VLOOKUP(KamstrupData[[#This Row],[IdLevel123]],'B-Business Capability'!B:L,10,FALSE) -> Customer Service and Support | R33: =VLOOKUP(KamstrupData[[#This Row],[IdLevel123]],'B-Business Capability'!B:L,11,FALSE) -> 0 | U33: =_xlfn.CONCAT(KamstrupData[[#This Row],[CountryCode]],"_",KamstrupData[[#This Row],[Business Area]],"_",KamstrupData[[#This Row],[DepartmentTeam]]) -> AT10_AT_Customer Service_ | V33: =VLOOKUP(KamstrupData[[#This Row],[ORG_Concat]],'O-Organization'!F:H,3,FALSE) -> 11025_AT10_Customer Service_AT_Customer Service_
D34: 4211-Customer Service-Customer Service and Support-Self-Service Engagement | E34: =VLOOKUP(D34,'B-Business Capability'!B:H,5,FALSE) -> Customer Service | F34: =VLOOKUP(D34,'B-Business Capability'!B:H,6,FALSE) -> Customer Service and Support | G34: =VLOOKUP(D34,'B-Business Capability'!B:H,7,FALSE) -> Self-Service Engagement | I34: AT10 | J34: AT_Customer Service | L34: 12 - My Kamstrup | M34: =VLOOKUP(L34,'A-Applications'!B:D,3,FALSE) -> My Kamstrup | N34: Tolerate | O34: Business Critical | P34: P13-Customer Service & Operation-- | Q34: =VLOOKUP(KamstrupData[[#This Row],[IdLevel123]],'B-Business Capability'!B:L,10,FALSE) -> Customer Service and Support | R34: =VLOOKUP(KamstrupData[[#This Row],[IdLevel123]],'B-Business Capability'!B:L,11,FALSE) -> 0 | U34: =_xlfn.CONCAT(KamstrupData[[#This Row],[CountryCode]],"_",KamstrupData[[#This Row],[Business Area]],"_",KamstrupData[[#This Row],[DepartmentTeam]]) -> AT10_AT_Customer Service_ | V34: =VLOOKUP(KamstrupData[[#This Row],[ORG_Concat]],'O-Organization'!F:H,3,FALSE) -> 11025_AT10_Customer Service_AT_Customer Service_
D35: 4211-Customer Service-Customer Service and Support-Self-Service Engagement | E35: =VLOOKUP(D35,'B-Business Capability'!B:H,5,FALSE) -> Customer Service | F35: =VLOOKUP(D35,'B-Business Capability'!B:H,6,FALSE) -> Customer Service and Support | G35: =VLOOKUP(D35,'B-Business Capability'!B:H,7,FALSE) -> Self-Service Engagement | I35: AT10 | J35: AT_Customer Service | L35: 12 - My Kamstrup | M35: =VLOOKUP(L35,'A-Applications'!B:D,3,FALSE) -> My Kamstrup | N35: Tolerate | O35: Business Critical | P35: P13-Customer Service & Operation-- | Q35: =VLOOKUP(KamstrupData[[#This Row],[IdLevel123]],'B-Business Capability'!B:L,10,FALSE) -> Customer Service and Support | R35: =VLOOKUP(KamstrupData[[#This Row],[IdLevel123]],'B-Business Capability'!B:L,11,FALSE) -> 0 | U35: =_xlfn.CONCAT(KamstrupData[[#This Row],[CountryCode]],"_",KamstrupData[[#This Row],[Business Area]],"_",KamstrupData[[#This Row],[DepartmentTeam]]) -> AT10_AT_Customer Service_ | V35: =VLOOKUP(KamstrupData[[#This Row],[ORG_Concat]],'O-Organization'!F:H,3,FALSE) -> 11025_AT10_Customer Service_AT_Customer Service_
D36: 4233-Customer Service-Customer Project Management-Project Management | E36: =VLOOKUP(D36,'B-Business Capability'!B:H,5,FALSE) -> Customer Service | F36: =VLOOKUP(D36,'B-Business Capability'!B:H,6,FALSE) -> Customer Project Management | G36: =VLOOKUP(D36,'B-Business Capability'!B:H,7,FALSE) -> Project Management | I36: AT10 | J36: AT_Customer Service | L36: 12 - My Kamstrup | M36: =VLOOKUP(L36,'A-Applications'!B:D,3,FALSE) -> My Kamstrup | N36: Tolerate | O36: Business Critical | P36: P13-Customer Service & Operation-- | Q36: =VLOOKUP(KamstrupData[[#This Row],[IdLevel123]],'B-Business Capability'!B:L,10,FALSE) -> Order-to-Cash (O2C) | R36: =VLOOKUP(KamstrupData[[#This Row],[IdLevel123]],'B-Business Capability'!B:L,11,FALSE) -> 0 | U36: =_xlfn.CONCAT(KamstrupData[[#This Row],[CountryCode]],"_",KamstrupData[[#This Row],[Business Area]],"_",KamstrupData[[#This Row],[DepartmentTeam]]) -> AT10_AT_Customer Service_ | V36: =VLOOKUP(KamstrupData[[#This Row],[ORG_Concat]],'O-Organization'!F:H,3,FALSE) -> 11025_AT10_Customer Service_AT_Customer Service_
D37: 998-Not mapped to capability-- | E37: =VLOOKUP(D37,'B-Business Capability'!B:H,5,FALSE) -> Not mapped to capability | F37: =VLOOKUP(D37,'B-Business Capability'!B:H,6,FALSE) -> 0 | G37: =VLOOKUP(D37,'B-Business Capability'!B:H,7,FALSE) -> 0 | I37: AT10 | J37: AT_Customer Service | L37: 132 - GreenShot | M37: =VLOOKUP(L37,'A-Applications'!B:D,3,FALSE) -> GreenShot | N37: Tolerate | O37: Administrative Service | P37: No-NoProcess-- | Q37: =VLOOKUP(KamstrupData[[#This Row],[IdLevel123]],'B-Business Capability'!B:L,10,FALSE) -> N/A | R37: =VLOOKUP(KamstrupData[[#This Row],[IdLevel123]],'B-Business Capability'!B:L,11,FALSE) -> 0 | U37: =_xlfn.CONCAT(KamstrupData[[#This Row],[CountryCode]],"_",KamstrupData[[#This Row],[Business Area]],"_",KamstrupData[[#This Row],[DepartmentTeam]]) -> AT10_AT_Customer Service_ | V37: =VLOOKUP(KamstrupData[[#This Row],[ORG_Concat]],'O-Organization'!F:H,3,FALSE) -> 11025_AT10_Customer Service_AT_Customer Service_
D38: 4233-Customer Service-Customer Project Management-Project Management | E38: =VLOOKUP(D38,'B-Business Capability'!B:H,5,FALSE) -> Customer Service | F38: =VLOOKUP(D38,'B-Business Capability'!B:H,6,FALSE) -> Customer Project Management | G38: =VLOOKUP(D38,'B-Business Capability'!B:H,7,FALSE) -> Project Management | I38: AT10 | J38: AT_Customer Service | L38: 142 - Notepad++(https://notepad-plus-plus.org/) | M38: =VLOOKUP(L38,'A-Applications'!B:D,3,FALSE) -> Notepad++(https://notepad-plus-plus.org/) | N38: Tolerate | O38: Business Operational | P38: P12-Customer Solution Deployment-- | Q38: =VLOOKUP(KamstrupData[[#This Row],[IdLevel123]],'B-Business Capability'!B:L,10,FALSE) -> Order-to-Cash (O2C) | R38: =VLOOKUP(KamstrupData[[#This Row],[IdLevel123]],'B-Business Capability'!B:L,11,FALSE) -> 0 | U38: =_xlfn.CONCAT(KamstrupData[[#This Row],[CountryCode]],"_",KamstrupData[[#This Row],[Business Area]],"_",KamstrupData[[#This Row],[DepartmentTeam]]) -> AT10_AT_Customer Service_ | V38: =VLOOKUP(KamstrupData[[#This Row],[ORG_Concat]],'O-Organization'!F:H,3,FALSE) -> 11025_AT10_Customer Service_AT_Customer Service_
D39: 998-Not mapped to capability-- | E39: =VLOOKUP(D39,'B-Business Capability'!B:H,5,FALSE) -> Not mapped to capability | F39: =VLOOKUP(D39,'B-Business Capability'!B:H,6,FALSE) -> 0 | G39: =VLOOKUP(D39,'B-Business Capability'!B:H,7,FALSE) -> 0 | I39: AT10 | J39: AT_Customer Service | L39: 149 - SnagIt | M39: =VLOOKUP(L39,'A-Applications'!B:D,3,FALSE) -> SnagIt | N39: Tolerate | O39: Administrative Service | P39: P12-Customer Solution Deployment-- | Q39: =VLOOKUP(KamstrupData[[#This Row],[IdLevel123]],'B-Business Capability'!B:L,10,FALSE) -> N/A | R39: =VLOOKUP(KamstrupData[[#This Row],[IdLevel123]],'B-Business Capability'!B:L,11,FALSE) -> 0 | U39: =_xlfn.CONCAT(KamstrupData[[#This Row],[CountryCode]],"_",KamstrupData[[#This Row],[Business Area]],"_",KamstrupData[[#This Row],[DepartmentTeam]]) -> AT10_AT_Customer Service_ | V39: =VLOOKUP(KamstrupData[[#This Row],[ORG_Concat]],'O-Organization'!F:H,3,FALSE) -> 11025_AT10_Customer Service_AT_Customer Service_
D40: 998-Not mapped to capability-- | E40: =VLOOKUP(D40,'B-Business Capability'!B:H,5,FALSE) -> Not mapped to capability | F40: =VLOOKUP(D40,'B-Business Capability'!B:H,6,FALSE) -> 0 | G40: =VLOOKUP(D40,'B-Business Capability'!B:H,7,FALSE) -> 0 | I40: AT10 | J40: AT_Customer Service | L40: 149 - SnagIt | M40: =VLOOKUP(L40,'A-Applications'!B:D,3,FALSE) -> SnagIt | N40: Tolerate | O40: Business Operational | P40: P-Not mapped to process-- | Q40: =VLOOKUP(KamstrupData[[#This Row],[IdLevel123]],'B-Business Capability'!B:L,10,FALSE) -> N/A | R40: =VLOOKUP(KamstrupData[[#This Row],[IdLevel123]],'B-Business Capability'!B:L,11,FALSE) -> 0 | U40: =_xlfn.CONCAT(KamstrupData[[#This Row],[CountryCode]],"_",KamstrupData[[#This Row],[Business Area]],"_",KamstrupData[[#This Row],[DepartmentTeam]]) -> AT10_AT_Customer Service_ | V40: =VLOOKUP(KamstrupData[[#This Row],[ORG_Concat]],'O-Organization'!F:H,3,FALSE) -> 11025_AT10_Customer Service_AT_Customer Service_
D41: 4203-Customer Service-Customer Service and Support-Service Request Management | E41: =VLOOKUP(D41,'B-Business Capability'!B:H,5,FALSE) -> Customer Service | F41: =VLOOKUP(D41,'B-Business Capability'!B:H,6,FALSE) -> Customer Service and Support | G41: =VLOOKUP(D41,'B-Business Capability'!B:H,7,FALSE) -> Service Request Management | I41: AT10 | J41: AT_Customer Service | L41: 15 - JIRA | M41: =VLOOKUP(L41,'A-Applications'!B:D,3,FALSE) -> JIRA | N41: Tolerate | O41: Business Operational | P41: P13-Customer Service & Operation-- | Q41: =VLOOKUP(KamstrupData[[#This Row],[IdLevel123]],'B-Business Capability'!B:L,10,FALSE) -> Customer Service and Support | R41: =VLOOKUP(KamstrupData[[#This Row],[IdLevel123]],'B-Business Capability'!B:L,11,FALSE) -> 0 | U41: =_xlfn.CONCAT(KamstrupData[[#This Row],[CountryCode]],"_",KamstrupData[[#This Row],[Business Area]],"_",KamstrupData[[#This Row],[DepartmentTeam]]) -> AT10_AT_Customer Service_ | V41: =VLOOKUP(KamstrupData[[#This Row],[ORG_Concat]],'O-Organization'!F:H,3,FALSE) -> 11025_AT10_Customer Service_AT_Customer Service_
...

Sheet A-Applications
D1: Name of the application | E1: Application group | F1: Introduction date of application. (Before 1/8-2025 all applications are set to 01-01-2025) | G1: Install Type - On Prem - Cloud - 3 party hosted - Edge Computing - Distributed Applications | H1: The Gartner TIME (Tolerate, Invest, Migrate, Eliminate) framework is the industry standard for planning and executing an application rationalization. It is a proven methodology for maximizing the business value of your application portfolio. | J1: Vendor Kamstrup purchace the application from | L1: Consultancy for the application | M1: The number of users for the application | N1: The current stage of the application | O1: End of life or Phase out date for the application (Format 31-06-2026) | R1: The URL of the application | S1: Business Owner of the application. Used for applications with no cost if handled in business | V1: Owner of the application. From cost sheet or if empty from Business owner | W1: Delete,Superusers of the application | Y1: Delete | Z1: EA Information related to closure of the application | AA1: Not relevant, SLA for the application | AB1: Not relevant, License responsible of the application | AC1: Sub component to applicatoin | AD1: Which applications are supported by the application. Eg. READy, OMNIA, etc | AE1: Primary in relation to cleanup track | AF1: The application contain AI features. If Yes the risk should be evaluated. | AG1: Set to "No" if the application are not used in capability mapping. Used for server licenses and so. | AH1: If the application are part of a Platform chose the platform. | AI1: Note on the application | AJ1: The recomendation for clean up | AK1: Reason for the recommendation | AL1: Workpackage size of the clousure (S, M, Project) | AM1: Security approved application | AN1: Security approved date | AO1: Security debt. Low Medium High (Inveigate are beeing security investigated) | AP1: Is this application seen as a crown jewel
H2: https://www.leanix.net/en/download/applying-the-gartner-time-framework-for-application-rationalization?utm_term=gartner%20time%20model&utm_source=bing&utm_medium=ppc&utm_campaign=EMEA-NORDIC_Application-Rationalization_AR_Search_ENG_B&hsa_acc=9751618594&hsa_cam=590193139&hsa_grp=1136896741662464&hsa_kw=gartner%20time%20model&hsa_mt=e&hsa_net=bing&hsa_src=o&hsa_tgt=kwd-71056741979861:loc-53&hsa_ad=&hsa_ver=3&msclkid=a7b7b4e697911d431c1dd255b34cacf3&utm_content=NORDIC_gartner-time-framework
B3: NoApplication | C3: No | D3: Application | E3: Application Group | F3: Introduction date | G3: Install type | H3: Gartner TIME | I3: Application Type | J3: Software Vendor | K3: ItemNumber | L3: Consultancy | M3: User base | N3: Lifecycle stage status | O3: Expected End-of-Life Year | P3: Replaced by | Q3: Details | R3: URL | S3: Business Owner | T3: Tier | U3: Details2 | V3: Owner | W3: Super User | X3: Named users | Y3: OLD-Data integration | Z3: Temp | AA3: SLA | AB3: Licens responsible | AC3: Sub component to | AD3: Supporting applications | AE3: Org | AF3: AI | AG3: Used in capabilitiy mapping | AH3: Platform | AI3: Clean up: Note | AJ3: Clean up: Recomendation | AK3: Clean up: Reason | AL3: Clean up: WP Size | AM3: Security approved | AN3: Security Approved date | AO3: Security debt | AP3: Crown Jewels
B4: =_xlfn.CONCAT(Applications[[#This Row],[No]]," - ",Applications[[#This Row],[Application]]) -> 1 - IFS ERP | C4: 1 | D4: IFS ERP | E4: Enterprise Platforms | F4: 45658 | G4: On Premise | H4: Invest | I4: Standard solutions | J4: IFS AB | L4: IFS | M4: 1000-> | N4: 1-Strategic | O4: 46813 | Q4: IFS Apps 10 has End of life 1-3-2028. Transsition for new version are projected. | T4: T0 | U4: Ny licensaftale, generel prisstigning | V4: =_xlfn.XLOOKUP(Applications[[#This Row],[NoApplication]],AApplicationCosts[NoApplication],AApplicationCosts[License Owner],Applications[[#This Row],[Business Owner]],0,1) -> KRNO | AB4: KRTI | AE4: Finans | AH4: IFS | AI4: Note for cleanup | AJ4: Keep as strategic | AK4: It is our ERP system | AM4: Yes | AN4: 45658 | AO4: Low | AP4: Crown Jewel_1
B5: =_xlfn.CONCAT(Applications[[#This Row],[No]]," - ",Applications[[#This Row],[Application]]) -> 2 - QAD ERP | C5: 2 | D5: QAD ERP | E5: Business | F5: 45658 | G5: On Premise | H5: Eliminate | I5: Standard solutions | J5: QAD Inc. | L5: Kamstrup | M5: 50-99 | N5: 8-Phase out | O5: 47484 | P5: IFS ERP | Q5: QAD ERP: QAD ERP is a cloud-based enterprise resource planning solution designed specifically for manufacturers. It offers comprehensive solutions for supply chain management, production planning, inventory control, quality management, and regulatory compliance | T5: T1-D | U5: Old ERP system, are only used for viewing of old data. Serial no., Sales invoice, Purchase invoice. Comment 20/11-2024 Ole F har talt lidt med div. I Service vedr. deres aktuelle brug af systemet. Det lyder til (og der kommer en opfølgning på det) at der er brug for meget lidt data. Så jeg vil foreslå at vi laver en analyse / export af disse data til et Excel ark, og derefter officielt lukker systemet 😊 /Ole | V5: =_xlfn.XLOOKUP(Applications[[#This Row],[NoApplication]],AApplicationCosts[NoApplication],AApplicationCosts[License Owner],Applications[[#This Row],[Business Owner]],0,1) -> KRNO | AB5: KRTI | AE5: Supply Chain | AH5: QAD | AI5: Jf. bogføringsloven skal noget data gemmes i 5 år (sidste fakturering i 2021). Fra Ole: Jeg tænker det betyder at MFG (som er endnu ældre - data fra 1997 .. 2011) også skal med. Blot til info: - Tænker det er et projekt o Vi skal have information om vores serienumre i mindst 20 år så vidt jeg ved. o Og mere detaljeret i ca 10 år o Begge dele må kunne gemmes i BI på en eller anden måde o Det vil også kræve ændringer i Integration – da de så vil skulle lave serial lookup i BI istedet for i QAD/MFG - En anden udfordring er nok at jeg er den eneste med QAD/MFG viden i Kamstrup. Ole | AL5: M
B6: =_xlfn.CONCAT(Applications[[#This Row],[No]]," - ",Applications[[#This Row],[Application]]) -> 3 - Aras Innovator PLM | C6: 3 | D6: Aras Innovator PLM | E6: Business | F6: 45658 | G6: On Premise | I6: Standard solutions | J6: Aras Corporation | L6: Aras | M6: 100-499 | N6: 1-Strategic | O6: 54788 | Q6: Aras Innovator PLM: Aras Innovator PLM is a flexible, scalable, and upgradeable product lifecycle management software. It supports manufacturers of complex, connected products in digitally transforming their engineering business. It includes features like parts management, change management, document management, and quality management | T6: T0 | U6: non-standard / potentiale for forbedring | V6: =_xlfn.XLOOKUP(Applications[[#This Row],[NoApplication]],AApplicationCosts[NoApplication],AApplicationCosts[License Owner],Applications[[#This Row],[Business Owner]],0,1) -> KRNO | X6: JES, AOE, FHB | AB6: FRFS | AE6: Supply Chain | AH6: Aras Innovator
B7: =_xlfn.CONCAT(Applications[[#This Row],[No]]," - ",Applications[[#This Row],[Application]]) -> 4 - Microsoft Dynamics 365 CE (Sales) | C7: 4 | D7: Microsoft Dynamics 365 CE (Sales) | E7: Enterprise Platforms | F7: 45658 | G7: Cloud | I7: Standard solutions | J7: Microsoft | K7: DGP-00003 | L7: Netcompany | M7: 100-499 | N7: 1-Strategic | O7: 54788 | Q7: Microsoft Dynamics 365 CE (Sales): Microsoft Dynamics 365 Customer Engagement (CE) Sales is a customer relationship management (CRM) solution that helps sales teams build strong relationships with customers, take actions based on insights, and close deals faster. It includes features like account and contact management, lead and opportunity management, and sales forecasting | R7: https://kamstrup.crm4.dynamics.com/ | S7: MIBN | T7: T0 | V7: =_xlfn.XLOOKUP(Applications[[#This Row],[NoApplication]],AApplicationCosts[NoApplication],AApplicationCosts[License Owner],Applications[[#This Row],[Business Owner]],0,1) -> ALK | AA7: SLA | AB7: Susanne, JTBN | AE7: Sales & Marketing | AF7: Yes | AH7: Dynamics 365
B8: =_xlfn.CONCAT(Applications[[#This Row],[No]]," - ",Applications[[#This Row],[Application]]) -> 5 - Oracle CPQ | C8: 5 | D8: Oracle CPQ | E8: Enterprise Platforms | F8: 45658 | I8: Standard solutions | J8: Oracle Corporation | L8: Solutionspace | M8: 100-499 | N8: 1-Strategic | O8: 54788 | Q8: Oracle CPQ: Oracle Configure, Price, Quote (CPQ) is a cloud-based application that helps sellers configure the right mix of products or services and create accurate, professional quotes to quickly meet their customers’ pricing needs. It streamlines the entire opportunity-to-quote-to-order process | T8: T0 | U8: General stigning | V8: =_xlfn.XLOOKUP(Applications[[#This Row],[NoApplication]],AApplicationCosts[NoApplication],AApplicationCosts[License Owner],Applications[[#This Row],[Business Owner]],0,1) -> ALK | AB8: JTBN | AE8: Sales & Marketing | AH8: Oracle
B9: =_xlfn.CONCAT(Applications[[#This Row],[No]]," - ",Applications[[#This Row],[Application]]) -> 6 - ServiceNow | C9: 6 | D9: ServiceNow | E9: Business | F9: 45658 | G9: Cloud | H9: Invest | I9: Standard solutions | J9: ServiceNow Inc. | L9: Devoteam | M9: 1000-> | N9: 1-Strategic | O9: 54788 | Q9: ServiceNow: ServiceNow is a cloud-based enterprise workflow automation platform delivered as Software-as-a-Service (SaaS). It automates various business processes, including IT service management, customer service management, and project approvals, on a single, centralized platform | T9: T0 | U9: ITSM, Web portal | V9: =_xlfn.XLOOKUP(Applications[[#This Row],[NoApplication]],AApplicationCosts[NoApplication],AApplicationCosts[License Owner],Applications[[#This Row],[Business Owner]],0,1) -> JEHT | AB9: JEHT | AE9: Supply Chain | AF9: Yes - Minimal Risk | AH9: ServiceNow
B10: =_xlfn.CONCAT(Applications[[#This Row],[No]]," - ",Applications[[#This Row],[Application]]) -> 7 - Reliance | C10: 7 | D10: Reliance | E10: Quality Management System | F10: 45658 | G10: Cloud | I10: Standard solutions | J10: Reliance Industries Limited | L10: ETQ | N10: 8-Phase out | O10: 46477 | Q10: Reliance: Reliance is a governance, risk, and compliance (GRC) software solution that helps organizations streamline their risk management processes, ensure regulatory compliance, and enhance overall operational efficiency | T10: T1-D | U10: QMS - Quality Management System | V10: =_xlfn.XLOOKUP(Applications[[#This Row],[NoApplication]],AApplicationCosts[NoApplication],AApplicationCosts[License Owner],Applications[[#This Row],[Business Owner]],0,1) -> KRNO | AE10: Quality | AI10: Phase out and move to IFS, ServiceNow and IPW. Info on phase out from KRNO. | AL10: Project-paused
B11: =_xlfn.CONCAT(Applications[[#This Row],[No]]," - ",Applications[[#This Row],[Application]]) -> 8 - Neuron | C11: 8 | D11: Neuron | E11: Integration Platforms | F11: 45658 | I11: Standard solutions | J11: Neuron ESB | L11: Integrator | N11: 8-Phase out | O11: 46387 | P11: Azure | Q11: Neuron: Neuron is a simulation environment for modeling individual neurons and networks of neurons. It provides tools for building, managing, and using models in a way that is numerically sound and computationally efficient | T11: T1-D | U11: Integration | V11: =_xlfn.XLOOKUP(Applications[[#This Row],[NoApplication]],AApplicationCosts[NoApplication],AApplicationCosts[License Owner],Applications[[#This Row],[Business Owner]],0,1) -> KRNO | AB11: FFM | AC11: 8 - Neuron | AE11: Digitalization | AI11: Project of phase out are started with Jeyant in integration team | AL11: Project-initiated
B12: =_xlfn.CONCAT(Applications[[#This Row],[No]]," - ",Applications[[#This Row],[Application]]) -> 9 - Orbit | C12: 9 | D12: Orbit | E12: Communication | F12: 45658 | G12: Cloud | I12: Standard solutions | J12: Secoya A/S, Orbit Online A/S | L12: Secoya A/S | M12: 50-99 | N12: 7-Potential for phase out | O12: 54788 | Q12: Orbit: Orbit is a reporting and analytics solution suitable for businesses of any size. It includes features like automated reporting, report exporting, and interactive dashboards to monitor business metrics and KPIs in real-time | T12: T1-D | U12: Project Sales, replaces Sharepoint 2003 site | V12: =_xlfn.XLOOKUP(Applications[[#This Row],[NoApplication]],AApplicationCosts[NoApplication],AApplicationCosts[License Owner],Applications[[#This Row],[Business Owner]],0,1) -> ASRN | AB12: FRFS | AE12: Supply Chain | AI12: Close | AL12: Project-paused
B13: =_xlfn.CONCAT(Applications[[#This Row],[No]]," - ",Applications[[#This Row],[Application]]) -> 10 - Encryption Key Service (EKS) | C13: 10 | D13: Encryption Key Service (EKS) | E13: Kamstrup - Customer Software | F13: 45658 | I13: Customer Experience | J13: Kamstrup | N13: 3-Kamstrup application | O13: 54788 | Q13: Encryption Key Service (EKS): EKS is a service that provides encryption key management for securing sensitive data. It integrates with various applications to ensure data is encrypted and protected throughout its lifecycle. Consist of many services | T13: T2 | V13: =_xlfn.XLOOKUP(Applications[[#This Row],[NoApplication]],AApplicationCosts[NoApplication],AApplicationCosts[License Owner],Applications[[#This Row],[Business Owner]],0,1) -> SSY, GCPE | AP13: Crown Jewel_1
B14: =_xlfn.CONCAT(Applications[[#This Row],[No]]," - ",Applications[[#This Row],[Application]]) -> 12 - My Kamstrup | C14: 12 | D14: My Kamstrup | E14: Business | F14: 45658 | I14: Customer Experience | J14: Kamstrup | M14: 1000-> | N14: 2-Important application | O14: 54788 | Q14: My Kamstrup: My Kamstrup is a customer portal platform that provides access to various Kamstrup applications and services. It includes features like user administration, encryption key management, subscription management, and case creation | T14: T2 | U14: FRFS info from US: MyKamstrup virker ikke ordentligt, aktiveringsmail ryger i spam ofte. Her burde man virkelig ændre på customer experience. | V14: =_xlfn.XLOOKUP(Applications[[#This Row],[NoApplication]],AApplicationCosts[NoApplication],AApplicationCosts[License Owner],Applications[[#This Row],[Business Owner]],0,1) -> 0 | AE14: Sales & Marketing
B15: =_xlfn.CONCAT(Applications[[#This Row],[No]]," - ",Applications[[#This Row],[Application]]) -> 15 - JIRA | C15: 15 | D15: JIRA | E15: Business | F15: 45658 | G15: Cloud | I15: Development Tools | J15: Atlassian | L15: Atlassian, Eficode A/S | M15: 500-999 | N15: 1-Strategic | O15: 54788 | Q15: JIRA: JIRA is a project management and issue-tracking software developed by Atlassian. It is used for bug tracking, issue tracking, and project management, and is widely used by software development teams. | T15: T0 | U15: Bitbucket is mostly used for code and code review | V15: =_xlfn.XLOOKUP(Applications[[#This Row],[NoApplication]],AApplicationCosts[NoApplication],AApplicationCosts[License Owner],Applications[[#This Row],[Business Owner]],0,1) -> LAAG | AB15: FRFS | AE15: Software, Hardware Departments | AH15: Atlassian | AK15: Strategic decision to use it
B16: =_xlfn.CONCAT(Applications[[#This Row],[No]]," - ",Applications[[#This Row],[Application]]) -> 16 - BitBucket | C16: 16 | D16: BitBucket | E16: Development and Programming | F16: 45658 | G16: Cloud | I16: Development Tools | J16: Atlassian | N16: 5-Investigate | O16: 54788 | Q16: BitBucket: BitBucket is a web-based version control repository hosting service owned by Atlassian. It supports Git and Mercurial version control systems and is used for source code management and collaboration. | S16: LAAG | T16: T1-D | U16: Jira is used for issue tracking and project management | V16: =_xlfn.XLOOKUP(Applications[[#This Row],[NoApplication]],AApplicationCosts[NoApplication],AApplicationCosts[License Owner],Applications[[#This Row],[Business Owner]],0,1) -> LAAG | AH16: Atlassian
B17: =_xlfn.CONCAT(Applications[[#This Row],[No]]," - ",Applications[[#This Row],[Application]]) -> 17 - TFS | C17: 17 | D17: TFS | E17: Development and Programming | F17: 45658 | I17: Development Tools | J17: Microsoft | N17: 5-Investigate | O17: 54788 | Q17: TFS: Team Foundation Server (TFS) is a Microsoft product that provides source code management, project management, and build automation for software development projects. It supports version control, work item tracking, and continuous integration. | T17: T2 | V17: =_xlfn.XLOOKUP(Applications[[#This Row],[NoApplication]],AApplicationCosts[NoApplication],AApplicationCosts[License Owner],Applications[[#This Row],[Business Owner]],0,1) -> 0
B18: =_xlfn.CONCAT(Applications[[#This Row],[No]]," - ",Applications[[#This Row],[Application]]) -> 18 - Microsoft Visual Studio Pro MSDN | C18: 18 | D18: Microsoft Visual Studio Pro MSDN | E18: Development and Programming | F18: 45658 | G18: Distributed Applications | I18: Development Tools | J18: Microsoft | K18: 77D-00111 | M18: 50-99 | N18: 1-Strategic | O18: 54788 | Q18: Microsoft Visual Studio: Microsoft Visual Studio is an integrated development environment (IDE) used for developing applications, websites, and services. It supports various programming languages and includes features like code editing, debugging, and testing. | T18: T0 | V18: =_xlfn.XLOOKUP(Applications[[#This Row],[NoApplication]],AApplicationCosts[NoApplication],AApplicationCosts[License Owner],Applications[[#This Row],[Business Owner]],0,1) -> LAAG | AB18: Susanne | AD18: IDE | AE18: Software, Hardware Departments | AH18: Microsoft Developper | AJ18: Tolerate/Invest | AK18: Widely used for .NET development
B19: =_xlfn.CONCAT(Applications[[#This Row],[No]]," - ",Applications[[#This Row],[Application]]) -> 19 - TMS | C19: 19 | D19: TMS | E19: Utilities and Miscellaneous | F19: 45658 | I19: ERP Integrated Solutions | J19: Transporeon | N19: 4-Saved for now | O19: 54788 | Q19: TMS: Transportation Management System (TMS) is a software solution that helps organizations manage and optimize their transportation operations. It includes features like route planning, carrier selection, shipment tracking, and freight payment. | S19: KRNO | T19: T3 | V19: =_xlfn.XLOOKUP(Applications[[#This Row],[NoApplication]],AApplicationCosts[NoApplication],AApplicationCosts[License Owner],Applications[[#This Row],[Business Owner]],0,1) -> KRNO | AE19: Supply Chain
B20: =_xlfn.CONCAT(Applications[[#This Row],[No]]," - ",Applications[[#This Row],[Application]]) -> 21 - Subscription Manager | C20: 21 | D20: Subscription Manager | E20: Utilities and Miscellaneous | F20: 45658 | I20: ERP Integrated Solutions | J20: Flexera Software | N20: 5-Investigate | O20: 54788 | Q20: Subscription Manager: Subscription Manager is a software solution that helps organizations manage their subscription-based services. It includes features like subscription billing, customer management, and analytics. | T20: T2 | V20: =_xlfn.XLOOKUP(Applications[[#This Row],[NoApplication]],AApplicationCosts[NoApplication],AApplicationCosts[License Owner],Applications[[#This Row],[Business Owner]],0,1) -> 0
B21: =_xlfn.CONCAT(Applications[[#This Row],[No]]," - ",Applications[[#This Row],[Application]]) -> 23 - Readsoft | C21: 23 | D21: Readsoft | E21: Business | F21: 45658 | I21: ERP Integrated Solutions | J21: Kofax | M21: 10-49 | N21: 4-Saved for now | O21: 54788 | Q21: Readsoft: Readsoft is a software solution for automating document processing. It includes features like optical character recognition (OCR), data extraction, and workflow automation to streamline document management processes. | T21: T2 | V21: =_xlfn.XLOOKUP(Applications[[#This Row],[NoApplication]],AApplicationCosts[NoApplication],AApplicationCosts[License Owner],Applications[[#This Row],[Business Owner]],0,1) -> 0 | AB21: KRTI | AE21: Finans | AI21: Set to Save for now with KRTI
B22: =_xlfn.CONCAT(Applications[[#This Row],[No]]," - ",Applications[[#This Row],[Application]]) -> 24 - Pipechain | C22: 24 | D22: Pipechain | E22: Utilities and Miscellaneous | F22: 45658 | I22: ERP Integrated Solutions | J22: Pipechain, Inc. | N22: 5-Investigate | O22: 54788 | T22: T2 | V22: =_xlfn.XLOOKUP(Applications[[#This Row],[NoApplication]],AApplicationCosts[NoApplication],AApplicationCosts[License Owner],Applications[[#This Row],[Business Owner]],0,1) -> 0
B23: =_xlfn.CONCAT(Applications[[#This Row],[No]]," - ",Applications[[#This Row],[Application]]) -> 25 - PJD 3P | C23: 25 | D23: PJD 3P | E23: Utilities and Miscellaneous | F23: 45658 | I23: Production IT | J23: PJD Group | N23: 5-Investigate | O23: 54788 | T23: T2 | V23: =_xlfn.XLOOKUP(Applications[[#This Row],[NoApplication]],AApplicationCosts[NoApplication],AApplicationCosts[License Owner],Applications[[#This Row],[Business Owner]],0,1) -> 0
B24: =_xlfn.CONCAT(Applications[[#This Row],[No]]," - ",Applications[[#This Row],[Application]]) -> 30 - Billing Com | C24: 30 | D24: Billing Com | E24: Utilities and Miscellaneous | F24: 45658 | I24: Service Tools | J24: Amdocs | N24: 5-Investigate | O24: 54788 | T24: T3 | V24: =_xlfn.XLOOKUP(Applications[[#This Row],[NoApplication]],AApplicationCosts[NoApplication],AApplicationCosts[License Owner],Applications[[#This Row],[Business Owner]],0,1) -> 0 | AE24: Supply Chain
